Workbook
Name CompoundingRate: Inputs!$D$2

Sheet Summary
A1: DETAILS | F1: EST. RETURNS | H1: DATE | L1: PRINCIPLE | R1: CASH FLOWS | X1: RETURNS
A2: Address | B2: Suburb | C2: FX | D2: Type | E2: Entity | F2: Return | G2: Months | H2: Start Date | I2: End Date | J2: Months | K2: Ownership | L2: Purchase Price | M2: Value | N2: Equity | O2: Debt | P2: LVR | Q2: Avg Equity | R2: Interest | S2: Other Costs | T2: Rent | U2: Income | V2: Sale Price | W2: Capital Gain | X2: Profit | Y2: Return | Z2: IRR | AA2: Net-tax IRR | AB2: real IRR
A3: 17|34 Hamilton St | B3: Rose Bay 2029 | C3: {=INDIRECT("'" & $A3& "'!R13")} -> AUD | D3: {=INDIRECT("'" & $A3& "'!R16")} -> Property | E3: {=INDIRECT("'" & $A3& "'!R10")} -> Shaun Reichman | F3: - | G3: - | H3: =MIN(INDIRECT("'" & $A3& "'!A:A")) -> 44351 | I3: {=IF(N3=0, LOOKUP(2, 1/(INDIRECT("'"&A3&"'!B:B")="Return"), INDIRECT("'"&A3&"'!A:A")), "")} | J3: =YEARFRAC(H3, IF(V3=0, NOW(), I3))*12 -> 48.8 | K3: {=INDIRECT("'" & $A3& "'!R6")} -> 1 | L3: {=INDIRECT("'" & $A3& "'!P3")} -> 3450000 | M3: {=INDIRECT("'" & $A3& "'!R3")} -> 3750000 | N3: {=INDIRECT("'" & $A3& "'!T3")} -> 215863.13 | O3: {=INDIRECT("'" & $A3& "'!V3")} -> 3534136.9 | P3: {=INDIRECT("'" & $A3& "'!V6")} -> 0.9424365 | Q3: {=INDIRECT("'" & $A3& "'!T6")} -> #VALUE! | R3: =-SUM(INDIRECT("'" & $A3& "'!G:G")) -> -318413.49 | S3: =-(SUM(INDIRECT("'"&$A3&"'!H:H"))) -> -279091.2 | T3: =SUM(INDIRECT("'" & $A3& "'!I:I")) -> 427960 | U3: =SUM(R3:T3) -> -169544.69 | V3: =SUM(INDIRECT("'" & $A3& "'!J:J")) -> 0 | W3: =IF(V3<>0, (V3-L3)*K3, 0) -> 0 | X3: =IF(V3>0, (V3-L3+R3+S3+T3)*K3, 0) -> 0 | Y3: =(X3/K3)/Q3 -> #VALUE! | Z3: {=IF(INDIRECT("'" & $A3& "'!X3")<>0, INDIRECT("'" & $A3& "'!X3"), "")} | AA3: {=IF(INDIRECT("'" & $A3& "'!X6")<>0, INDIRECT("'" & $A3& "'!X6"), "")} | AB3: {=IF(INDIRECT("'" & $A3& "'!X9")<>0, INDIRECT("'" & $A3& "'!X9"), "")}

Sheet 17|34 Hamilton St
G1: INTEREST | H1: COSTS | I1: RENT | J1: SALE | K1: TAX | AA1: VALUATION | AC1: AVERAGE BALANCE | AG1: IRR CALCULATIONS | AL1: NET IRR CALCULATIONS | AP1: FINANCING IRR CALCULATIONS
A2: Date | B2: Transaction | C2: Debt | D2: Equity | E2: Cash Flow | F2: Repayment | G2: Amount | H2: Amount | I2: Income | J2: Amount | K2: Earnings | L2: Rate | M2: Debt Cost (est.) | P2: Purchase Price | R2: Value | T2: Equity | V2: Debt | X2: IRR | AA2: Purchase Price | AB2: Value | AC2: Equity | AD2: Debt | AE2: Days | AG2: Cash Flows | AH2: Days | AI2: PV | AJ2: Sum To Zero | AL2: Cash Flows | AM2: PV | AN2: Sum To Zero | AP2: Last Date | AQ2: Date | AR2: Balance | AS2: Rate | AT2: Interest | AU2: Cash Flows | AV2: PV | AW2: Sum To Zero | AX2: Ave Rate
A3: 44351 | B3: Deposit to Vendor | D3: 172500 | E3: -172500 | M3: =IF($A3<>"", IF(ISNUMBER(SEARCH("Debt Cost (est.)",B3)), SUMIFS(AT:AT, AQ:AQ, ">="&DATE("20"&RIGHT(LEFT(B3,4),2)-1,7,1), AQ:AQ, "<="&DATE("20"&RIGHT(LEFT(B3,4),2),6,30)), ""), "") | P3: 3450000 | R3: =V3+T3 -> 3750000 | T3: {=LOOKUP(2,1/(AC:AC<>""),AC:AC)} -> 215863.13 | V3: {=LOOKUP(2,1/(AD:AD<>""),AD:AD)} -> 3534136.9 | AA3: =IF($A3<>"", MIN(AB3,$P$3), "") -> 172500 | AB3: =AD3+AC3 -> 172500 | AC3: =D3 -> 172500 | AD3: 0 | AE3: =IF(A5<>"", A5-A3, IF(A3<>"",IF(AC3<>0,TODAY()-A3,0), "")) -> 41 | AG3: =IF($A3<>"", I3+J3+E3-F3-H3, "") -> -172500 | AH3: =IF(A3<>"", A3-A$3, "") -> 0 | AI3: =IF(A3<>"", AG3*(1+$X$3)^-(AH3/365), "") -> -172500 | AJ3: =SUM(AI:AI) -> -85407.82 | AL3: =IF($A3<>"", AG3-IF(ISNUMBER(K3),K3*L3,0), "") -> -172500 | AM3: =IF(A3<>"", AL3*(1+$X$6/CompoundingRate)^-(AH3/(365/CompoundingRate)), "") -> -172500 | AN3: =SUM(AM:AM) -> -96003.982 | AP3: =IF(T3=0, MAX(A:A), TODAY()) -> 45836 | AQ3: =A3 -> 44351 | AR3: =IF($AQ3<>"", INDEX($AC$3:$AC$1055, MATCH($AQ3,$A$3:$A$1055,1)), "") -> 172500 | AS3: =IF($AQ3<>"", INDEX(Inputs!$B$3:$B$101, MATCH($AQ3,Inputs!$A$3:$A$101,1)), "") -> 0.001 | AT3: =IF($AQ3<>"", AR3*AS3/365, "") -> 0.47260274 | AU3: =IF($AQ3<>"", SUMIFS($AL$3:$AL$1054, $A$3:$A$1054,$AQ3) + SUMIFS($M$3:$M$1054, $A$3:$A$1054,$AQ3)*IFERROR(AVERAGEIFS($L$3:$L$1054, $A$3:$A$1054,$AQ3, $M$3:$M$1054,">0"),0) - AT3, "") -> -172500.47 | AV3: =IF(AQ3<>"", AU3*(1+$X$9/CompoundingRate)^-((AQ3-AQ$3)/(365/CompoundingRate)), "") -> -172500.47 | AW3: =SUM(AV:AV) -> -160561.45 | AX3: =SUMPRODUCT(AR:AR,AS:AS)/SUM(AR:AR) -> 0.030269514 | BA3: 42917 | BB3: 43281 | BC3: =COUNTIFS(AQ:AQ,">="&BA3, AQ:AQ,"<="&BB3, AR:AR, "<>0") -> 0 | BD3: =AVERAGEIFS(AR:AR, AQ:AQ,">="&BA3, AQ:AQ,"<="&BB3, AR:AR, "<>0") -> #DIV/0!
A4: 44377 | B4: FY21 Debt Cost (est.) | L4: 0.325 | M4: =IF($A4<>"", IF(ISNUMBER(SEARCH("Debt Cost (est.)",B4)), SUMIFS(AT:AT, AQ:AQ, ">="&DATE("20"&RIGHT(LEFT(B4,4),2)-1,7,1), AQ:AQ, "<="&DATE("20"&RIGHT(LEFT(B4,4),2),6,30)), ""), "") -> 12.760274 | AA4: =IF($A4<>"", MIN(AB4,$P$3), "") -> 172500 | AB4: =IF($A4<>"", AC4+AD4, "") -> 172500 | AC4: =IF(A4<>"", AC3+D4+F4-G4, "") -> 172500 | AD4: =IF(A4<>"", AD3+C4-F4+G4, "") -> 0 | AE4: =IF(A5<>"", A5-A4, IF(A4<>"",IF(AC4<>0,TODAY()-A4,0), "")) -> 15 | AG4: =IF($A4<>"", I4+J4+E4-F4-H4, "") -> 0 | AH4: =IF(A4<>"", A4-A$3, "") -> 26 | AI4: =IF(A4<>"", AG4*(1+$X$3)^-(AH4/365), "") -> 0 | AL4: =IF($A4<>"", AG4-IF(ISNUMBER(K4),K4*L4,0), "") -> 0 | AM4: =IF(A4<>"", AL4*(1+$X$6/CompoundingRate)^-(AH4/(365/CompoundingRate)), "") -> 0 | AQ4: =IF(AQ3<$AP$3,AQ3+1,"") -> 44352 | AR4: =IF($AQ4<>"", INDEX($AC$3:$AC$1055, MATCH($AQ4,$A$3:$A$1055,1)), "") -> 172500 | AS4: =IF($AQ4<>"", INDEX(Inputs!$B$3:$B$101, MATCH($AQ4,Inputs!$A$3:$A$101,1)), "") -> 0.001 | AT4: =IF($AQ4<>"", AR4*AS4/365, "") -> 0.47260274 | AU4: =IF($AQ4<>"", SUMIFS($AL$3:$AL$1054, $A$3:$A$1054,$AQ4) + SUMIFS($M$3:$M$1054, $A$3:$A$1054,$AQ4)*IFERROR(AVERAGEIFS($L$3:$L$1054, $A$3:$A$1054,$AQ4, $M$3:$M$1054,">0"),0) - AT4, "") -> -0.47260274 | AV4: =IF(AQ4<>"", AU4*(1+$X$9/CompoundingRate)^-((AQ4-AQ$3)/(365/CompoundingRate)), "") -> -0.47260274 | BA4: 43282 | BB4: 43646 | BC4: =COUNTIFS(AQ:AQ,">="&BA4, AQ:AQ,"<="&BB4, AR:AR, "<>0") -> 0 | BD4: =AVERAGEIFS(AR:AR, AQ:AQ,">="&BA4, AQ:AQ,"<="&BB4, AR:AR, "<>0") -> #DIV/0!
A5: 44392 | B5: Payment to Vendor | D5: 345000 | E5: -345000 | M5: =IF($A5<>"", IF(ISNUMBER(SEARCH("Debt Cost (est.)",B5)), SUMIFS(AT:AT, AQ:AQ, ">="&DATE("20"&RIGHT(LEFT(B5,4),2)-1,7,1), AQ:AQ, "<="&DATE("20"&RIGHT(LEFT(B5,4),2),6,30)), ""), "") | R5: Ownership | T5: Avg Equity | V5: LVR | X5: Net-tax IRR | AA5: =IF($A5<>"", MIN(AB5,$P$3), "") -> 517500 | AB5: =IF($A5<>"", AC5+AD5, "") -> 517500 | AC5: =IF(A5<>"", AC4+D5+F5-G5, "") -> 517500 | AD5: =IF(A5<>"", AD4+C5-F5+G5, "") -> 0 | AE5: =IF(A6<>"", A6-A5, IF(A5<>"",IF(AC5<>0,TODAY()-A5,0), "")) -> 0 | AG5: =IF($A5<>"", I5+J5+E5-F5-H5, "") -> -345000 | AH5: =IF(A5<>"", A5-A$3, "") -> 41 | AI5: =IF(A5<>"", AG5*(1+$X$3)^-(AH5/365), "") -> -345000 | AL5: =IF($A5<>"", AG5-IF(ISNUMBER(K5),K5*L5,0), "") -> -345000 | AM5: =IF(A5<>"", AL5*(1+$X$6/CompoundingRate)^-(AH5/(365/CompoundingRate)), "") -> -345000 | AQ5: =IF(AQ4<$AP$3,AQ4+1,"") -> 44353 | AR5: =IF($AQ5<>"", INDEX($AC$3:$AC$1055, MATCH($AQ5,$A$3:$A$1055,1)), "") -> 172500 | AS5: =IF($AQ5<>"", INDEX(Inputs!$B$3:$B$101, MATCH($AQ5,Inputs!$A$3:$A$101,1)), "") -> 0.001 | AT5: =IF($AQ5<>"", AR5*AS5/365, "") -> 0.47260274 | AU5: =IF($AQ5<>"", SUMIFS($AL$3:$AL$1054, $A$3:$A$1054,$AQ5) + SUMIFS($M$3:$M$1054, $A$3:$A$1054,$AQ5)*IFERROR(AVERAGEIFS($L$3:$L$1054, $A$3:$A$1054,$AQ5, $M$3:$M$1054,">0"),0) - AT5, "") -> -0.47260274 | AV5: =IF(AQ5<>"", AU5*(1+$X$9/CompoundingRate)^-((AQ5-AQ$3)/(365/CompoundingRate)), "") -> -0.47260274 | BA5: 43647 | BB5: 44012 | BC5: =COUNTIFS(AQ:AQ,">="&BA5, AQ:AQ,"<="&BB5, AR:AR, "<>0") -> 0 | BD5: =AVERAGEIFS(AR:AR, AQ:AQ,">="&BA5, AQ:AQ,"<="&BB5, AR:AR, "<>0") -> #DIV/0!
A6: 44392 | B6: NAB Mortgage #3063 | C6: 2432500 | M6: =IF($A6<>"", IF(ISNUMBER(SEARCH("Debt Cost (est.)",B6)), SUMIFS(AT:AT, AQ:AQ, ">="&DATE("20"&RIGHT(LEFT(B6,4),2)-1,7,1), AQ:AQ, "<="&DATE("20"&RIGHT(LEFT(B6,4),2),6,30)), ""), "") | R6: 1 | T6: =SUMPRODUCT(AC:AC,AE:AE)/SUM(AE:AE) -> #VALUE! | V6: =V3/R3 -> 0.9424365 | AA6: =IF($A6<>"", MIN(AB6,$P$3), "") -> 2950000 | AB6: =IF($A6<>"", AC6+AD6, "") -> 2950000 | AC6: =IF(A6<>"", AC5+D6+F6-G6, "") -> 517500 | AD6: =IF(A6<>"", AD5+C6-F6+G6, "") -> 2432500 | AE6: =IF(A7<>"", A7-A6, IF(A6<>"",IF(AC6<>0,TODAY()-A6,0), "")) -> 0 | AG6: =IF($A6<>"", I6+J6+E6-F6-H6, "") -> 0 | AH6: =IF(A6<>"", A6-A$3, "") -> 41 | AI6: =IF(A6<>"", AG6*(1+$X$3)^-(AH6/365), "") -> 0 | AL6: =IF($A6<>"", AG6-IF(ISNUMBER(K6),K6*L6,0), "") -> 0 | AM6: =IF(A6<>"", AL6*(1+$X$6/CompoundingRate)^-(AH6/(365/CompoundingRate)), "") -> 0 | AQ6: =IF(AQ5<$AP$3,AQ5+1,"") -> 44354 | AR6: =IF($AQ6<>"", INDEX($AC$3:$AC$1055, MATCH($AQ6,$A$3:$A$1055,1)), "") -> 172500 | AS6: =IF($AQ6<>"", INDEX(Inputs!$B$3:$B$101, MATCH($AQ6,Inputs!$A$3:$A$101,1)), "") -> 0.001 | AT6: =IF($AQ6<>"", AR6*AS6/365, "") -> 0.47260274 | AU6: =IF($AQ6<>"", SUMIFS($AL$3:$AL$1054, $A$3:$A$1054,$AQ6) + SUMIFS($M$3:$M$1054, $A$3:$A$1054,$AQ6)*IFERROR(AVERAGEIFS($L$3:$L$1054, $A$3:$A$1054,$AQ6, $M$3:$M$1054,">0"),0) - AT6, "") -> -0.47260274 | AV6: =IF(AQ6<>"", AU6*(1+$X$9/CompoundingRate)^-((AQ6-AQ$3)/(365/CompoundingRate)), "") -> -0.47260274 | BA6: 44013 | BB6: 44377 | BC6: =COUNTIFS(AQ:AQ,">="&BA6, AQ:AQ,"<="&BB6, AR:AR, "<>0") -> 27 | BD6: =AVERAGEIFS(AR:AR, AQ:AQ,">="&BA6, AQ:AQ,"<="&BB6, AR:AR, "<>0") -> 172500
A7: 44392 | B7: NAB Mortgage #2157 | C7: 500000 | M7: =IF($A7<>"", IF(ISNUMBER(SEARCH("Debt Cost (est.)",B7)), SUMIFS(AT:AT, AQ:AQ, ">="&DATE("20"&RIGHT(LEFT(B7,4),2)-1,7,1), AQ:AQ, "<="&DATE("20"&RIGHT(LEFT(B7,4),2),6,30)), ""), "") | AA7: =IF($A7<>"", MIN(AB7,$P$3), "") -> 3450000 | AB7: =IF($A7<>"", AC7+AD7, "") -> 3450000 | AC7: =IF(A7<>"", AC6+D7+F7-G7, "") -> 517500 | AD7: =IF(A7<>"", AD6+C7-F7+G7, "") -> 2932500 | AE7: =IF(A8<>"", A8-A7, IF(A7<>"",IF(AC7<>0,TODAY()-A7,0), "")) -> 0 | AG7: =IF($A7<>"", I7+J7+E7-F7-H7, "") -> 0 | AH7: =IF(A7<>"", A7-A$3, "") -> 41 | AI7: =IF(A7<>"", AG7*(1+$X$3)^-(AH7/365), "") -> 0 | AL7: =IF($A7<>"", AG7-IF(ISNUMBER(K7),K7*L7,0), "") -> 0 | AM7: =IF(A7<>"", AL7*(1+$X$6/CompoundingRate)^-(AH7/(365/CompoundingRate)), "") -> 0 | AQ7: =IF(AQ6<$AP$3,AQ6+1,"") -> 44355 | AR7: =IF($AQ7<>"", INDEX($AC$3:$AC$1055, MATCH($AQ7,$A$3:$A$1055,1)), "") -> 172500 | AS7: =IF($AQ7<>"", INDEX(Inputs!$B$3:$B$101, MATCH($AQ7,Inputs!$A$3:$A$101,1)), "") -> 0.001 | AT7: =IF($AQ7<>"", AR7*AS7/365, "") -> 0.47260274 | AU7: =IF($AQ7<>"", SUMIFS($AL$3:$AL$1054, $A$3:$A$1054,$AQ7) + SUMIFS($M$3:$M$1054, $A$3:$A$1054,$AQ7)*IFERROR(AVERAGEIFS($L$3:$L$1054, $A$3:$A$1054,$AQ7, $M$3:$M$1054,">0"),0) - AT7, "") -> -0.47260274 | AV7: =IF(AQ7<>"", AU7*(1+$X$9/CompoundingRate)^-((AQ7-AQ$3)/(365/CompoundingRate)), "") -> -0.47260274 | BA7: 44378 | BB7: 44742 | BC7: =COUNTIFS(AQ:AQ,">="&BA7, AQ:AQ,"<="&BB7, AR:AR, "<>0") -> 365 | BD7: =AVERAGEIFS(AR:AR, AQ:AQ,">="&BA7, AQ:AQ,"<="&BB7, AR:AR, "<>0") -> 540545.38
A8: 44392 | B8: Stamp Duty | H8: 180010 | M8: =IF($A8<>"", IF(ISNUMBER(SEARCH("Debt Cost (est.)",B8)), SUMIFS(AT:AT, AQ:AQ, ">="&DATE("20"&RIGHT(LEFT(B8,4),2)-1,7,1), AQ:AQ, "<="&DATE("20"&RIGHT(LEFT(B8,4),2),6,30)), ""), "") | X8: real IRR | AA8: =IF($A8<>"", MIN(AB8,$P$3), "") -> 3450000 | AB8: =IF($A8<>"", AC8+AD8, "") -> 3450000 | AC8: =IF(A8<>"", AC7+D8+F8-G8, "") -> 517500 | AD8: =IF(A8<>"", AD7+C8-F8+G8, "") -> 2932500 | AE8: =IF(A9<>"", A9-A8, IF(A8<>"",IF(AC8<>0,TODAY()-A8,0), "")) -> 0 | AG8: =IF($A8<>"", I8+J8+E8-F8-H8, "") -> -180010 | AH8: =IF(A8<>"", A8-A$3, "") -> 41 | AI8: =IF(A8<>"", AG8*(1+$X$3)^-(AH8/365), "") -> -180010 | AL8: =IF($A8<>"", AG8-IF(ISNUMBER(K8),K8*L8,0), "") -> -180010 | AM8: =IF(A8<>"", AL8*(1+$X$6/CompoundingRate)^-(AH8/(365/CompoundingRate)), "") -> -180010 | AQ8: =IF(AQ7<$AP$3,AQ7+1,"") -> 44356 | AR8: =IF($AQ8<>"", INDEX($AC$3:$AC$1055, MATCH($AQ8,$A$3:$A$1055,1)), "") -> 172500 | AS8: =IF($AQ8<>"", INDEX(Inputs!$B$3:$B$101, MATCH($AQ8,Inputs!$A$3:$A$101,1)), "") -> 0.001 | AT8: =IF($AQ8<>"", AR8*AS8/365, "") -> 0.47260274 | AU8: =IF($AQ8<>"", SUMIFS($AL$3:$AL$1054, $A$3:$A$1054,$AQ8) + SUMIFS($M$3:$M$1054, $A$3:$A$1054,$AQ8)*IFERROR(AVERAGEIFS($L$3:$L$1054, $A$3:$A$1054,$AQ8, $M$3:$M$1054,">0"),0) - AT8, "") -> -0.47260274 | AV8: =IF(AQ8<>"", AU8*(1+$X$9/CompoundingRate)^-((AQ8-AQ$3)/(365/CompoundingRate)), "") -> -0.47260274 | BA8: 44743 | BB8: 45107 | BC8: =COUNTIFS(AQ:AQ,">="&BA8, AQ:AQ,"<="&BB8, AR:AR, "<>0") -> 365 | BD8: =AVERAGEIFS(AR:AR, AQ:AQ,">="&BA8, AQ:AQ,"<="&BB8, AR:AR, "<>0") -> 636307
A9: 44392 | B9: Lawyer Settlement Fees | H9: 4622.8 | M9: =IF($A9<>"", IF(ISNUMBER(SEARCH("Debt Cost (est.)",B9)), SUMIFS(AT:AT, AQ:AQ, ">="&DATE("20"&RIGHT(LEFT(B9,4),2)-1,7,1), AQ:AQ, "<="&DATE("20"&RIGHT(LEFT(B9,4),2),6,30)), ""), "") | R9: Entity | AA9: =IF($A9<>"", MIN(AB9,$P$3), "") -> 3450000 | AB9: =IF($A9<>"", AC9+AD9, "") -> 3450000 | AC9: =IF(A9<>"", AC8+D9+F9-G9, "") -> 517500 | AD9: =IF(A9<>"", AD8+C9-F9+G9, "") -> 2932500 | AE9: =IF(A10<>"", A10-A9, IF(A9<>"",IF(AC9<>0,TODAY()-A9,0), "")) -> 0 | AG9: =IF($A9<>"", I9+J9+E9-F9-H9, "") -> -4622.8 | AH9: =IF(A9<>"", A9-A$3, "") -> 41 | AI9: =IF(A9<>"", AG9*(1+$X$3)^-(AH9/365), "") -> -4622.8 | AL9: =IF($A9<>"", AG9-IF(ISNUMBER(K9),K9*L9,0), "") -> -4622.8 | AM9: =IF(A9<>"", AL9*(1+$X$6/CompoundingRate)^-(AH9/(365/CompoundingRate)), "") -> -4622.8 | AQ9: =IF(AQ8<$AP$3,AQ8+1,"") -> 44357 | AR9: =IF($AQ9<>"", INDEX($AC$3:$AC$1055, MATCH($AQ9,$A$3:$A$1055,1)), "") -> 172500 | AS9: =IF($AQ9<>"", INDEX(Inputs!$B$3:$B$101, MATCH($AQ9,Inputs!$A$3:$A$101,1)), "") -> 0.001 | AT9: =IF($AQ9<>"", AR9*AS9/365, "") -> 0.47260274 | AU9: =IF($AQ9<>"", SUMIFS($AL$3:$AL$1054, $A$3:$A$1054,$AQ9) + SUMIFS($M$3:$M$1054, $A$3:$A$1054,$AQ9)*IFERROR(AVERAGEIFS($L$3:$L$1054, $A$3:$A$1054,$AQ9, $M$3:$M$1054,">0"),0) - AT9, "") -> -0.47260274 | AV9: =IF(AQ9<>"", AU9*(1+$X$9/CompoundingRate)^-((AQ9-AQ$3)/(365/CompoundingRate)), "") -> -0.47260274 | BA9: 45108 | BB9: 45473 | BC9: =COUNTIFS(AQ:AQ,">="&BA9, AQ:AQ,"<="&BB9, AR:AR, "<>0") -> 366 | BD9: =AVERAGEIFS(AR:AR, AQ:AQ,">="&BA9, AQ:AQ,"<="&BB9, AR:AR, "<>0") -> 729079.84
A10: 44392 | B10: NAB Mortgage Fee | H10: =9.87+147.7+147.7+147.7 -> 452.97 | M10: =IF($A10<>"", IF(ISNUMBER(SEARCH("Debt Cost (est.)",B10)), SUMIFS(AT:AT, AQ:AQ, ">="&DATE("20"&RIGHT(LEFT(B10,4),2)-1,7,1), AQ:AQ, "<="&DATE("20"&RIGHT(LEFT(B10,4),2),6,30)), ""), "") | R10: Shaun Reichman | AA10: =IF($A10<>"", MIN(AB10,$P$3), "") -> 3450000 | AB10: =IF($A10<>"", AC10+AD10, "") -> 3450000 | AC10: =IF(A10<>"", AC9+D10+F10-G10, "") -> 517500 | AD10: =IF(A10<>"", AD9+C10-F10+G10, "") -> 2932500 | AE10: =IF(A11<>"", A11-A10, IF(A10<>"",IF(AC10<>0,TODAY()-A10,0), "")) -> 0 | AG10: =IF($A10<>"", I10+J10+E10-F10-H10, "") -> -452.97 | AH10: =IF(A10<>"", A10-A$3, "") -> 41 | AI10: =IF(A10<>"", AG10*(1+$X$3)^-(AH10/365), "") -> -452.97 | AL10: =IF($A10<>"", AG10-IF(ISNUMBER(K10),K10*L10,0), "") -> -452.97 | AM10: =IF(A10<>"", AL10*(1+$X$6/CompoundingRate)^-(AH10/(365/CompoundingRate)), "") -> -452.97 | AQ10: =IF(AQ9<$AP$3,AQ9+1,"") -> 44358 | AR10: =IF($AQ10<>"", INDEX($AC$3:$AC$1055, MATCH($AQ10,$A$3:$A$1055,1)), "") -> 172500 | AS10: =IF($AQ10<>"", INDEX(Inputs!$B$3:$B$101, MATCH($AQ10,Inputs!$A$3:$A$101,1)), "") -> 0.001 | AT10: =IF($AQ10<>"", AR10*AS10/365, "") -> 0.47260274 | AU10: =IF($AQ10<>"", SUMIFS($AL$3:$AL$1054, $A$3:$A$1054,$AQ10) + SUMIFS($M$3:$M$1054, $A$3:$A$1054,$AQ10)*IFERROR(AVERAGEIFS($L$3:$L$1054, $A$3:$A$1054,$AQ10, $M$3:$M$1054,">0"),0) - AT10, "") -> -0.47260274 | AV10: =IF(AQ10<>"", AU10*(1+$X$9/CompoundingRate)^-((AQ10-AQ$3)/(365/CompoundingRate)), "") -> -0.47260274 | BA10: 45474 | BB10: 45838 | BC10: =COUNTIFS(AQ:AQ,">="&BA10, AQ:AQ,"<="&BB10, AR:AR, "<>0") -> 363 | BD10: =AVERAGEIFS(AR:AR, AQ:AQ,">="&BA10, AQ:AQ,"<="&BB10, AR:AR, "<>0") -> 562311.48
A11: 44392 | B11: Pexa Settlement Fee | H11: 117.92 | M11: =IF($A11<>"", IF(ISNUMBER(SEARCH("Debt Cost (est.)",B11)), SUMIFS(AT:AT, AQ:AQ, ">="&DATE("20"&RIGHT(LEFT(B11,4),2)-1,7,1), AQ:AQ, "<="&DATE("20"&RIGHT(LEFT(B11,4),2),6,30)), ""), "") | AA11: =IF($A11<>"", MIN(AB11,$P$3), "") -> 3450000 | AB11: =IF($A11<>"", AC11+AD11, "") -> 3450000 | AC11: =IF(A11<>"", AC10+D11+F11-G11, "") -> 517500 | AD11: =IF(A11<>"", AD10+C11-F11+G11, "") -> 2932500 | AE11: =IF(A12<>"", A12-A11, IF(A11<>"",IF(AC11<>0,TODAY()-A11,0), "")) -> 0 | AG11: =IF($A11<>"", I11+J11+E11-F11-H11, "") -> -117.92 | AH11: =IF(A11<>"", A11-A$3, "") -> 41 | AI11: =IF(A11<>"", AG11*(1+$X$3)^-(AH11/365), "") -> -117.92 | AL11: =IF($A11<>"", AG11-IF(ISNUMBER(K11),K11*L11,0), "") -> -117.92 | AM11: =IF(A11<>"", AL11*(1+$X$6/CompoundingRate)^-(AH11/(365/CompoundingRate)), "") -> -117.92 | AQ11: =IF(AQ10<$AP$3,AQ10+1,"") -> 44359 | AR11: =IF($AQ11<>"", INDEX($AC$3:$AC$1055, MATCH($AQ11,$A$3:$A$1055,1)), "") -> 172500 | AS11: =IF($AQ11<>"", INDEX(Inputs!$B$3:$B$101, MATCH($AQ11,Inputs!$A$3:$A$101,1)), "") -> 0.001 | AT11: =IF($AQ11<>"", AR11*AS11/365, "") -> 0.47260274 | AU11: =IF($AQ11<>"", SUMIFS($AL$3:$AL$1054, $A$3:$A$1054,$AQ11) + SUMIFS($M$3:$M$1054, $A$3:$A$1054,$AQ11)*IFERROR(AVERAGEIFS($L$3:$L$1054, $A$3:$A$1054,$AQ11, $M$3:$M$1054,">0"),0) - AT11, "") -> -0.47260274 | AV11: =IF(AQ11<>"", AU11*(1+$X$9/CompoundingRate)^-((AQ11-AQ$3)/(365/CompoundingRate)), "") -> -0.47260274
A12: 44392 | B12: Registration Fees | H12: 443.1 | M12: =IF($A12<>"", IF(ISNUMBER(SEARCH("Debt Cost (est.)",B12)), SUMIFS(AT:AT, AQ:AQ, ">="&DATE("20"&RIGHT(LEFT(B12,4),2)-1,7,1), AQ:AQ, "<="&DATE("20"&RIGHT(LEFT(B12,4),2),6,30)), ""), "") | R12: Currency | AA12: =IF($A12<>"", MIN(AB12,$P$3), "") -> 3450000 | AB12: =IF($A12<>"", AC12+AD12, "") -> 3450000 | AC12: =IF(A12<>"", AC11+D12+F12-G12, "") -> 517500 | AD12: =IF(A12<>"", AD11+C12-F12+G12, "") -> 2932500 | AE12: =IF(A13<>"", A13-A12, IF(A12<>"",IF(AC12<>0,TODAY()-A12,0), "")) -> 0 | AG12: =IF($A12<>"", I12+J12+E12-F12-H12, "") -> -443.1 | AH12: =IF(A12<>"", A12-A$3, "") -> 41 | AI12: =IF(A12<>"", AG12*(1+$X$3)^-(AH12/365), "") -> -443.1 | AL12: =IF($A12<>"", AG12-IF(ISNUMBER(K12),K12*L12,0), "") -> -443.1 | AM12: =IF(A12<>"", AL12*(1+$X$6/CompoundingRate)^-(AH12/(365/CompoundingRate)), "") -> -443.1 | AQ12: =IF(AQ11<$AP$3,AQ11+1,"") -> 44360 | AR12: =IF($AQ12<>"", INDEX($AC$3:$AC$1055, MATCH($AQ12,$A$3:$A$1055,1)), "") -> 172500 | AS12: =IF($AQ12<>"", INDEX(Inputs!$B$3:$B$101, MATCH($AQ12,Inputs!$A$3:$A$101,1)), "") -> 0.001 | AT12: =IF($AQ12<>"", AR12*AS12/365, "") -> 0.47260274 | AU12: =IF($AQ12<>"", SUMIFS($AL$3:$AL$1054, $A$3:$A$1054,$AQ12) + SUMIFS($M$3:$M$1054, $A$3:$A$1054,$AQ12)*IFERROR(AVERAGEIFS($L$3:$L$1054, $A$3:$A$1054,$AQ12, $M$3:$M$1054,">0"),0) - AT12, "") -> -0.47260274 | AV12: =IF(AQ12<>"", AU12*(1+$X$9/CompoundingRate)^-((AQ12-AQ$3)/(365/CompoundingRate)), "") -> -0.47260274
A13: 44392 | B13: Section 184 Certificate | H13: 119.9 | M13: =IF($A13<>"", IF(ISNUMBER(SEARCH("Debt Cost (est.)",B13)), SUMIFS(AT:AT, AQ:AQ, ">="&DATE("20"&RIGHT(LEFT(B13,4),2)-1,7,1), AQ:AQ, "<="&DATE("20"&RIGHT(LEFT(B13,4),2),6,30)), ""), "") | R13: AUD | AA13: =IF($A13<>"", MIN(AB13,$P$3), "") -> 3450000 | AB13: =IF($A13<>"", AC13+AD13, "") -> 3450000 | AC13: =IF(A13<>"", AC12+D13+F13-G13, "") -> 517500 | AD13: =IF(A13<>"", AD12+C13-F13+G13, "") -> 2932500 | AE13: =IF(A14<>"", A14-A13, IF(A13<>"",IF(AC13<>0,TODAY()-A13,0), "")) -> 0 | AG13: =IF($A13<>"", I13+J13+E13-F13-H13, "") -> -119.9 | AH13: =IF(A13<>"", A13-A$3, "") -> 41 | AI13: =IF(A13<>"", AG13*(1+$X$3)^-(AH13/365), "") -> -119.9 | AL13: =IF($A13<>"", AG13-IF(ISNUMBER(K13),K13*L13,0), "") -> -119.9 | AM13: =IF(A13<>"", AL13*(1+$X$6/CompoundingRate)^-(AH13/(365/CompoundingRate)), "") -> -119.9 | AQ13: =IF(AQ12<$AP$3,AQ12+1,"") -> 44361 | AR13: =IF($AQ13<>"", INDEX($AC$3:$AC$1055, MATCH($AQ13,$A$3:$A$1055,1)), "") -> 172500 | AS13: =IF($AQ13<>"", INDEX(Inputs!$B$3:$B$101, MATCH($AQ13,Inputs!$A$3:$A$101,1)), "") -> 0.001 | AT13: =IF($AQ13<>"", AR13*AS13/365, "") -> 0.47260274 | AU13: =IF($AQ13<>"", SUMIFS($AL$3:$AL$1054, $A$3:$A$1054,$AQ13) + SUMIFS($M$3:$M$1054, $A$3:$A$1054,$AQ13)*IFERROR(AVERAGEIFS($L$3:$L$1054, $A$3:$A$1054,$AQ13, $M$3:$M$1054,">0"),0) - AT13, "") -> -0.47260274 | AV13: =IF(AQ13<>"", AU13*(1+$X$9/CompoundingRate)^-((AQ13-AQ$3)/(365/CompoundingRate)), "") -> -0.47260274
A14: 44392 | B14: Discharge of Mortgage | H14: -147.7 | M14: =IF($A14<>"", IF(ISNUMBER(SEARCH("Debt Cost (est.)",B14)), SUMIFS(AT:AT, AQ:AQ, ">="&DATE("20"&RIGHT(LEFT(B14,4),2)-1,7,1), AQ:AQ, "<="&DATE("20"&RIGHT(LEFT(B14,4),2),6,30)), ""), "") | AA14: =IF($A14<>"", MIN(AB14,$P$3), "") -> 3450000 | AB14: =IF($A14<>"", AC14+AD14, "") -> 3450000 | AC14: =IF(A14<>"", AC13+D14+F14-G14, "") -> 517500 | AD14: =IF(A14<>"", AD13+C14-F14+G14, "") -> 2932500 | AE14: =IF(A15<>"", A15-A14, IF(A14<>"",IF(AC14<>0,TODAY()-A14,0), "")) -> 0 | AG14: =IF($A14<>"", I14+J14+E14-F14-H14, "") -> 147.7 | AH14: =IF(A14<>"", A14-A$3, "") -> 41 | AI14: =IF(A14<>"", AG14*(1+$X$3)^-(AH14/365), "") -> 147.7 | AL14: =IF($A14<>"", AG14-IF(ISNUMBER(K14),K14*L14,0), "") -> 147.7 | AM14: =IF(A14<>"", AL14*(1+$X$6/CompoundingRate)^-(AH14/(365/CompoundingRate)), "") -> 147.7 | AQ14: =IF(AQ13<$AP$3,AQ13+1,"") -> 44362 | AR14: =IF($AQ14<>"", INDEX($AC$3:$AC$1055, MATCH($AQ14,$A$3:$A$1055,1)), "") -> 172500 | AS14: =IF($AQ14<>"", INDEX(Inputs!$B$3:$B$101, MATCH($AQ14,Inputs!$A$3:$A$101,1)), "") -> 0.001 | AT14: =IF($AQ14<>"", AR14*AS14/365, "") -> 0.47260274 | AU14: =IF($AQ14<>"", SUMIFS($AL$3:$AL$1054, $A$3:$A$1054,$AQ14) + SUMIFS($M$3:$M$1054, $A$3:$A$1054,$AQ14)*IFERROR(AVERAGEIFS($L$3:$L$1054, $A$3:$A$1054,$AQ14, $M$3:$M$1054,">0"),0) - AT14, "") -> -0.47260274 | AV14: =IF(AQ14<>"", AU14*(1+$X$9/CompoundingRate)^-((AQ14-AQ$3)/(365/CompoundingRate)), "") -> -0.47260274
A15: 44392 | B15: Additional Settlement Amount | H15: 35 | M15: =IF($A15<>"", IF(ISNUMBER(SEARCH("Debt Cost (est.)",B15)), SUMIFS(AT:AT, AQ:AQ, ">="&DATE("20"&RIGHT(LEFT(B15,4),2)-1,7,1), AQ:AQ, "<="&DATE("20"&RIGHT(LEFT(B15,4),2),6,30)), ""), "") | R15: Type | AA15: =IF($A15<>"", MIN(AB15,$P$3), "") -> 3450000 | AB15: =IF($A15<>"", AC15+AD15, "") -> 3450000 | AC15: =IF(A15<>"", AC14+D15+F15-G15, "") -> 517500 | AD15: =IF(A15<>"", AD14+C15-F15+G15, "") -> 2932500 | AE15: =IF(A16<>"", A16-A15, IF(A15<>"",IF(AC15<>0,TODAY()-A15,0), "")) -> 0 | AG15: =IF($A15<>"", I15+J15+E15-F15-H15, "") -> -35 | AH15: =IF(A15<>"", A15-A$3, "") -> 41 | AI15: =IF(A15<>"", AG15*(1+$X$3)^-(AH15/365), "") -> -35 | AL15: =IF($A15<>"", AG15-IF(ISNUMBER(K15),K15*L15,0), "") -> -35 | AM15: =IF(A15<>"", AL15*(1+$X$6/CompoundingRate)^-(AH15/(365/CompoundingRate)), "") -> -35 | AQ15: =IF(AQ14<$AP$3,AQ14+1,"") -> 44363 | AR15: =IF($AQ15<>"", INDEX($AC$3:$AC$1055, MATCH($AQ15,$A$3:$A$1055,1)), "") -> 172500 | AS15: =IF($AQ15<>"", INDEX(Inputs!$B$3:$B$101, MATCH($AQ15,Inputs!$A$3:$A$101,1)), "") -> 0.001 | AT15: =IF($AQ15<>"", AR15*AS15/365, "") -> 0.47260274 | AU15: =IF($AQ15<>"", SUMIFS($AL$3:$AL$1054, $A$3:$A$1054,$AQ15) + SUMIFS($M$3:$M$1054, $A$3:$A$1054,$AQ15)*IFERROR(AVERAGEIFS($L$3:$L$1054, $A$3:$A$1054,$AQ15, $M$3:$M$1054,">0"),0) - AT15, "") -> -0.47260274 | AV15: =IF(AQ15<>"", AU15*(1+$X$9/CompoundingRate)^-((AQ15-AQ$3)/(365/CompoundingRate)), "") -> -0.47260274
A16: 44392 | B16: Shortfall of Funds | H16: 286.95 | M16: =IF($A16<>"", IF(ISNUMBER(SEARCH("Debt Cost (est.)",B16)), SUMIFS(AT:AT, AQ:AQ, ">="&DATE("20"&RIGHT(LEFT(B16,4),2)-1,7,1), AQ:AQ, "<="&DATE("20"&RIGHT(LEFT(B16,4),2),6,30)), ""), "") | R16: Property | AA16: =IF($A16<>"", MIN(AB16,$P$3), "") -> 3450000 | AB16: =IF($A16<>"", AC16+AD16, "") -> 3450000 | AC16: =IF(A16<>"", AC15+D16+F16-G16, "") -> 517500 | AD16: =IF(A16<>"", AD15+C16-F16+G16, "") -> 2932500 | AE16: =IF(A17<>"", A17-A16, IF(A16<>"",IF(AC16<>0,TODAY()-A16,0), "")) -> 0 | AG16: =IF($A16<>"", I16+J16+E16-F16-H16, "") -> -286.95 | AH16: =IF(A16<>"", A16-A$3, "") -> 41 | AI16: =IF(A16<>"", AG16*(1+$X$3)^-(AH16/365), "") -> -286.95 | AL16: =IF($A16<>"", AG16-IF(ISNUMBER(K16),K16*L16,0), "") -> -286.95 | AM16: =IF(A16<>"", AL16*(1+$X$6/CompoundingRate)^-(AH16/(365/CompoundingRate)), "") -> -286.95 | AQ16: =IF(AQ15<$AP$3,AQ15+1,"") -> 44364 | AR16: =IF($AQ16<>"", INDEX($AC$3:$AC$1055, MATCH($AQ16,$A$3:$A$1055,1)), "") -> 172500 | AS16: =IF($AQ16<>"", INDEX(Inputs!$B$3:$B$101, MATCH($AQ16,Inputs!$A$3:$A$101,1)), "") -> 0.001 | AT16: =IF($AQ16<>"", AR16*AS16/365, "") -> 0.47260274 | AU16: =IF($AQ16<>"", SUMIFS($AL$3:$AL$1054, $A$3:$A$1054,$AQ16) + SUMIFS($M$3:$M$1054, $A$3:$A$1054,$AQ16)*IFERROR(AVERAGEIFS($L$3:$L$1054, $A$3:$A$1054,$AQ16, $M$3:$M$1054,">0"),0) - AT16, "") -> -0.47260274 | AV16: =IF(AQ16<>"", AU16*(1+$X$9/CompoundingRate)^-((AQ16-AQ$3)/(365/CompoundingRate)), "") -> -0.47260274
A17: 44392 | B17: Council Rates | H17: 1470.73 | M17: =IF($A17<>"", IF(ISNUMBER(SEARCH("Debt Cost (est.)",B17)), SUMIFS(AT:AT, AQ:AQ, ">="&DATE("20"&RIGHT(LEFT(B17,4),2)-1,7,1), AQ:AQ, "<="&DATE("20"&RIGHT(LEFT(B17,4),2),6,30)), ""), "") | AA17: =IF($A17<>"", MIN(AB17,$P$3), "") -> 3450000 | AB17: =IF($A17<>"", AC17+AD17, "") -> 3450000 | AC17: =IF(A17<>"", AC16+D17+F17-G17, "") -> 517500 | AD17: =IF(A17<>"", AD16+C17-F17+G17, "") -> 2932500 | AE17: =IF(A18<>"", A18-A17, IF(A17<>"",IF(AC17<>0,TODAY()-A17,0), "")) -> 0 | AG17: =IF($A17<>"", I17+J17+E17-F17-H17, "") -> -1470.73 | AH17: =IF(A17<>"", A17-A$3, "") -> 41 | AI17: =IF(A17<>"", AG17*(1+$X$3)^-(AH17/365), "") -> -1470.73 | AL17: =IF($A17<>"", AG17-IF(ISNUMBER(K17),K17*L17,0), "") -> -1470.73 | AM17: =IF(A17<>"", AL17*(1+$X$6/CompoundingRate)^-(AH17/(365/CompoundingRate)), "") -> -1470.73 | AQ17: =IF(AQ16<$AP$3,AQ16+1,"") -> 44365 | AR17: =IF($AQ17<>"", INDEX($AC$3:$AC$1055, MATCH($AQ17,$A$3:$A$1055,1)), "") -> 172500 | AS17: =IF($AQ17<>"", INDEX(Inputs!$B$3:$B$101, MATCH($AQ17,Inputs!$A$3:$A$101,1)), "") -> 0.001 | AT17: =IF($AQ17<>"", AR17*AS17/365, "") -> 0.47260274 | AU17: =IF($AQ17<>"", SUMIFS($AL$3:$AL$1054, $A$3:$A$1054,$AQ17) + SUMIFS($M$3:$M$1054, $A$3:$A$1054,$AQ17)*IFERROR(AVERAGEIFS($L$3:$L$1054, $A$3:$A$1054,$AQ17, $M$3:$M$1054,">0"),0) - AT17, "") -> -0.47260274 | AV17: =IF(AQ17<>"", AU17*(1+$X$9/CompoundingRate)^-((AQ17-AQ$3)/(365/CompoundingRate)), "") -> -0.47260274
A18: 44392 | B18: Water Rates | H18: 131.66 | M18: =IF($A18<>"", IF(ISNUMBER(SEARCH("Debt Cost (est.)",B18)), SUMIFS(AT:AT, AQ:AQ, ">="&DATE("20"&RIGHT(LEFT(B18,4),2)-1,7,1), AQ:AQ, "<="&DATE("20"&RIGHT(LEFT(B18,4),2),6,30)), ""), "") | AA18: =IF($A18<>"", MIN(AB18,$P$3), "") -> 3450000 | AB18: =IF($A18<>"", AC18+AD18, "") -> 3450000 | AC18: =IF(A18<>"", AC17+D18+F18-G18, "") -> 517500 | AD18: =IF(A18<>"", AD17+C18-F18+G18, "") -> 2932500 | AE18: =IF(A19<>"", A19-A18, IF(A18<>"",IF(AC18<>0,TODAY()-A18,0), "")) -> 0 | AG18: =IF($A18<>"", I18+J18+E18-F18-H18, "") -> -131.66 | AH18: =IF(A18<>"", A18-A$3, "") -> 41 | AI18: =IF(A18<>"", AG18*(1+$X$3)^-(AH18/365), "") -> -131.66 | AL18: =IF($A18<>"", AG18-IF(ISNUMBER(K18),K18*L18,0), "") -> -131.66 | AM18: =IF(A18<>"", AL18*(1+$X$6/CompoundingRate)^-(AH18/(365/CompoundingRate)), "") -> -131.66 | AQ18: =IF(AQ17<$AP$3,AQ17+1,"") -> 44366 | AR18: =IF($AQ18<>"", INDEX($AC$3:$AC$1055, MATCH($AQ18,$A$3:$A$1055,1)), "") -> 172500 | AS18: =IF($AQ18<>"", INDEX(Inputs!$B$3:$B$101, MATCH($AQ18,Inputs!$A$3:$A$101,1)), "") -> 0.001 | AT18: =IF($AQ18<>"", AR18*AS18/365, "") -> 0.47260274 | AU18: =IF($AQ18<>"", SUMIFS($AL$3:$AL$1054, $A$3:$A$1054,$AQ18) + SUMIFS($M$3:$M$1054, $A$3:$A$1054,$AQ18)*IFERROR(AVERAGEIFS($L$3:$L$1054, $A$3:$A$1054,$AQ18, $M$3:$M$1054,">0"),0) - AT18, "") -> -0.47260274 | AV18: =IF(AQ18<>"", AU18*(1+$X$9/CompoundingRate)^-((AQ18-AQ$3)/(365/CompoundingRate)), "") -> -0.47260274
A19: 44392 | B19: Land Tax | H19: 3407.78 | M19: =IF($A19<>"", IF(ISNUMBER(SEARCH("Debt Cost (est.)",B19)), SUMIFS(AT:AT, AQ:AQ, ">="&DATE("20"&RIGHT(LEFT(B19,4),2)-1,7,1), AQ:AQ, "<="&DATE("20"&RIGHT(LEFT(B19,4),2),6,30)), ""), "") | AA19: =IF($A19<>"", MIN(AB19,$P$3), "") -> 3450000 | AB19: =IF($A19<>"", AC19+AD19, "") -> 3450000 | AC19: =IF(A19<>"", AC18+D19+F19-G19, "") -> 517500 | AD19: =IF(A19<>"", AD18+C19-F19+G19, "") -> 2932500 | AE19: =IF(A20<>"", A20-A19, IF(A19<>"",IF(AC19<>0,TODAY()-A19,0), "")) -> 0 | AG19: =IF($A19<>"", I19+J19+E19-F19-H19, "") -> -3407.78 | AH19: =IF(A19<>"", A19-A$3, "") -> 41 | AI19: =IF(A19<>"", AG19*(1+$X$3)^-(AH19/365), "") -> -3407.78 | AL19: =IF($A19<>"", AG19-IF(ISNUMBER(K19),K19*L19,0), "") -> -3407.78 | AM19: =IF(A19<>"", AL19*(1+$X$6/CompoundingRate)^-(AH19/(365/CompoundingRate)), "") -> -3407.78 | AQ19: =IF(AQ18<$AP$3,AQ18+1,"") -> 44367 | AR19: =IF($AQ19<>"", INDEX($AC$3:$AC$1055, MATCH($AQ19,$A$3:$A$1055,1)), "") -> 172500 | AS19: =IF($AQ19<>"", INDEX(Inputs!$B$3:$B$101, MATCH($AQ19,Inputs!$A$3:$A$101,1)), "") -> 0.001 | AT19: =IF($AQ19<>"", AR19*AS19/365, "") -> 0.47260274 | AU19: =IF($AQ19<>"", SUMIFS($AL$3:$AL$1054, $A$3:$A$1054,$AQ19) + SUMIFS($M$3:$M$1054, $A$3:$A$1054,$AQ19)*IFERROR(AVERAGEIFS($L$3:$L$1054, $A$3:$A$1054,$AQ19, $M$3:$M$1054,">0"),0) - AT19, "") -> -0.47260274 | AV19: =IF(AQ19<>"", AU19*(1+$X$9/CompoundingRate)^-((AQ19-AQ$3)/(365/CompoundingRate)), "") -> -0.47260274
A20: 44392 | B20: Strata Levies | H20: 325.22 | M20: =IF($A20<>"", IF(ISNUMBER(SEARCH("Debt Cost (est.)",B20)), SUMIFS(AT:AT, AQ:AQ, ">="&DATE("20"&RIGHT(LEFT(B20,4),2)-1,7,1), AQ:AQ, "<="&DATE("20"&RIGHT(LEFT(B20,4),2),6,30)), ""), "") | AA20: =IF($A20<>"", MIN(AB20,$P$3), "") -> 3450000 | AB20: =IF($A20<>"", AC20+AD20, "") -> 3450000 | AC20: =IF(A20<>"", AC19+D20+F20-G20, "") -> 517500 | AD20: =IF(A20<>"", AD19+C20-F20+G20, "") -> 2932500 | AE20: =IF(A21<>"", A21-A20, IF(A20<>"",IF(AC20<>0,TODAY()-A20,0), "")) -> 1 | AG20: =IF($A20<>"", I20+J20+E20-F20-H20, "") -> -325.22 | AH20: =IF(A20<>"", A20-A$3, "") -> 41 | AI20: =IF(A20<>"", AG20*(1+$X$3)^-(AH20/365), "") -> -325.22 | AL20: =IF($A20<>"", AG20-IF(ISNUMBER(K20),K20*L20,0), "") -> -325.22 | AM20: =IF(A20<>"", AL20*(1+$X$6/CompoundingRate)^-(AH20/(365/CompoundingRate)), "") -> -325.22 | AQ20: =IF(AQ19<$AP$3,AQ19+1,"") -> 44368 | AR20: =IF($AQ20<>"", INDEX($AC$3:$AC$1055, MATCH($AQ20,$A$3:$A$1055,1)), "") -> 172500 | AS20: =IF($AQ20<>"", INDEX(Inputs!$B$3:$B$101, MATCH($AQ20,Inputs!$A$3:$A$101,1)), "") -> 0.001 | AT20: =IF($AQ20<>"", AR20*AS20/365, "") -> 0.47260274 | AU20: =IF($AQ20<>"", SUMIFS($AL$3:$AL$1054, $A$3:$A$1054,$AQ20) + SUMIFS($M$3:$M$1054, $A$3:$A$1054,$AQ20)*IFERROR(AVERAGEIFS($L$3:$L$1054, $A$3:$A$1054,$AQ20, $M$3:$M$1054,">0"),0) - AT20, "") -> -0.47260274 | AV20: =IF(AQ20<>"", AU20*(1+$X$9/CompoundingRate)^-((AQ20-AQ$3)/(365/CompoundingRate)), "") -> -0.47260274
A21: 44393 | B21: Billi | H21: 2020 | M21: =IF($A21<>"", IF(ISNUMBER(SEARCH("Debt Cost (est.)",B21)), SUMIFS(AT:AT, AQ:AQ, ">="&DATE("20"&RIGHT(LEFT(B21,4),2)-1,7,1), AQ:AQ, "<="&DATE("20"&RIGHT(LEFT(B21,4),2),6,30)), ""), "") | AA21: =IF($A21<>"", MIN(AB21,$P$3), "") -> 3450000 | AB21: =IF($A21<>"", AC21+AD21, "") -> 3450000 | AC21: =IF(A21<>"", AC20+D21+F21-G21, "") -> 517500 | AD21: =IF(A21<>"", AD20+C21-F21+G21, "") -> 2932500 | AE21: =IF(A22<>"", A22-A21, IF(A21<>"",IF(AC21<>0,TODAY()-A21,0), "")) -> 0 | AG21: =IF($A21<>"", I21+J21+E21-F21-H21, "") -> -2020 | AH21: =IF(A21<>"", A21-A$3, "") -> 42 | AI21: =IF(A21<>"", AG21*(1+$X$3)^-(AH21/365), "") -> -2020 | AL21: =IF($A21<>"", AG21-IF(ISNUMBER(K21),K21*L21,0), "") -> -2020 | AM21: =IF(A21<>"", AL21*(1+$X$6/CompoundingRate)^-(AH21/(365/CompoundingRate)), "") -> -2020 | AQ21: =IF(AQ20<$AP$3,AQ20+1,"") -> 44369 | AR21: =IF($AQ21<>"", INDEX($AC$3:$AC$1055, MATCH($AQ21,$A$3:$A$1055,1)), "") -> 172500 | AS21: =IF($AQ21<>"", INDEX(Inputs!$B$3:$B$101, MATCH($AQ21,Inputs!$A$3:$A$101,1)), "") -> 0.001 | AT21: =IF($AQ21<>"", AR21*AS21/365, "") -> 0.47260274 | AU21: =IF($AQ21<>"", SUMIFS($AL$3:$AL$1054, $A$3:$A$1054,$AQ21) + SUMIFS($M$3:$M$1054, $A$3:$A$1054,$AQ21)*IFERROR(AVERAGEIFS($L$3:$L$1054, $A$3:$A$1054,$AQ21, $M$3:$M$1054,">0"),0) - AT21, "") -> -0.47260274 | AV21: =IF(AQ21<>"", AU21*(1+$X$9/CompoundingRate)^-((AQ21-AQ$3)/(365/CompoundingRate)), "") -> -0.47260274
A22: 44393 | B22: Locksmith | H22: 180 | M22: =IF($A22<>"", IF(ISNUMBER(SEARCH("Debt Cost (est.)",B22)), SUMIFS(AT:AT, AQ:AQ, ">="&DATE("20"&RIGHT(LEFT(B22,4),2)-1,7,1), AQ:AQ, "<="&DATE("20"&RIGHT(LEFT(B22,4),2),6,30)), ""), "") | AA22: =IF($A22<>"", MIN(AB22,$P$3), "") -> 3450000 | AB22: =IF($A22<>"", AC22+AD22, "") -> 3450000 | AC22: =IF(A22<>"", AC21+D22+F22-G22, "") -> 517500 | AD22: =IF(A22<>"", AD21+C22-F22+G22, "") -> 2932500 | AE22: =IF(A23<>"", A23-A22, IF(A22<>"",IF(AC22<>0,TODAY()-A22,0), "")) -> 0 | AG22: =IF($A22<>"", I22+J22+E22-F22-H22, "") -> -180 | AH22: =IF(A22<>"", A22-A$3, "") -> 42 | AI22: =IF(A22<>"", AG22*(1+$X$3)^-(AH22/365), "") -> -180 | AL22: =IF($A22<>"", AG22-IF(ISNUMBER(K22),K22*L22,0), "") -> -180 | AM22: =IF(A22<>"", AL22*(1+$X$6/CompoundingRate)^-(AH22/(365/CompoundingRate)), "") -> -180 | AQ22: =IF(AQ21<$AP$3,AQ21+1,"") -> 44370 | AR22: =IF($AQ22<>"", INDEX($AC$3:$AC$1055, MATCH($AQ22,$A$3:$A$1055,1)), "") -> 172500 | AS22: =IF($AQ22<>"", INDEX(Inputs!$B$3:$B$101, MATCH($AQ22,Inputs!$A$3:$A$101,1)), "") -> 0.001 | AT22: =IF($AQ22<>"", AR22*AS22/365, "") -> 0.47260274 | AU22: =IF($AQ22<>"", SUMIFS($AL$3:$AL$1054, $A$3:$A$1054,$AQ22) + SUMIFS($M$3:$M$1054, $A$3:$A$1054,$AQ22)*IFERROR(AVERAGEIFS($L$3:$L$1054, $A$3:$A$1054,$AQ22, $M$3:$M$1054,">0"),0) - AT22, "") -> -0.47260274 | AV22: =IF(AQ22<>"", AU22*(1+$X$9/CompoundingRate)^-((AQ22-AQ$3)/(365/CompoundingRate)), "") -> -0.47260274
A23: 44393 | B23: Insinkerator | H23: 1090 | M23: =IF($A23<>"", IF(ISNUMBER(SEARCH("Debt Cost (est.)",B23)), SUMIFS(AT:AT, AQ:AQ, ">="&DATE("20"&RIGHT(LEFT(B23,4),2)-1,7,1), AQ:AQ, "<="&DATE("20"&RIGHT(LEFT(B23,4),2),6,30)), ""), "") | AA23: =IF($A23<>"", MIN(AB23,$P$3), "") -> 3450000 | AB23: =IF($A23<>"", AC23+AD23, "") -> 3450000 | AC23: =IF(A23<>"", AC22+D23+F23-G23, "") -> 517500 | AD23: =IF(A23<>"", AD22+C23-F23+G23, "") -> 2932500 | AE23: =IF(A24<>"", A24-A23, IF(A23<>"",IF(AC23<>0,TODAY()-A23,0), "")) -> 0 | AG23: =IF($A23<>"", I23+J23+E23-F23-H23, "") -> -1090 | AH23: =IF(A23<>"", A23-A$3, "") -> 42 | AI23: =IF(A23<>"", AG23*(1+$X$3)^-(AH23/365), "") -> -1090 | AL23: =IF($A23<>"", AG23-IF(ISNUMBER(K23),K23*L23,0), "") -> -1090 | AM23: =IF(A23<>"", AL23*(1+$X$6/CompoundingRate)^-(AH23/(365/CompoundingRate)), "") -> -1090 | AQ23: =IF(AQ22<$AP$3,AQ22+1,"") -> 44371 | AR23: =IF($AQ23<>"", INDEX($AC$3:$AC$1055, MATCH($AQ23,$A$3:$A$1055,1)), "") -> 172500 | AS23: =IF($AQ23<>"", INDEX(Inputs!$B$3:$B$101, MATCH($AQ23,Inputs!$A$3:$A$101,1)), "") -> 0.001 | AT23: =IF($AQ23<>"", AR23*AS23/365, "") -> 0.47260274 | AU23: =IF($AQ23<>"", SUMIFS($AL$3:$AL$1054, $A$3:$A$1054,$AQ23) + SUMIFS($M$3:$M$1054, $A$3:$A$1054,$AQ23)*IFERROR(AVERAGEIFS($L$3:$L$1054, $A$3:$A$1054,$AQ23, $M$3:$M$1054,">0"),0) - AT23, "") -> -0.47260274 | AV23: =IF(AQ23<>"", AU23*(1+$X$9/CompoundingRate)^-((AQ23-AQ$3)/(365/CompoundingRate)), "") -> -0.47260274
A24: 44393 | B24: Blinds | H24: =2500+4749 -> 7249 | M24: =IF($A24<>"", IF(ISNUMBER(SEARCH("Debt Cost (est.)",B24)), SUMIFS(AT:AT, AQ:AQ, ">="&DATE("20"&RIGHT(LEFT(B24,4),2)-1,7,1), AQ:AQ, "<="&DATE("20"&RIGHT(LEFT(B24,4),2),6,30)), ""), "") | AA24: =IF($A24<>"", MIN(AB24,$P$3), "") -> 3450000 | AB24: =IF($A24<>"", AC24+AD24, "") -> 3450000 | AC24: =IF(A24<>"", AC23+D24+F24-G24, "") -> 517500 | AD24: =IF(A24<>"", AD23+C24-F24+G24, "") -> 2932500 | AE24: =IF(A25<>"", A25-A24, IF(A24<>"",IF(AC24<>0,TODAY()-A24,0), "")) -> 0 | AG24: =IF($A24<>"", I24+J24+E24-F24-H24, "") -> -7249 | AH24: =IF(A24<>"", A24-A$3, "") -> 42 | AI24: =IF(A24<>"", AG24*(1+$X$3)^-(AH24/365), "") -> -7249 | AL24: =IF($A24<>"", AG24-IF(ISNUMBER(K24),K24*L24,0), "") -> -7249 | AM24: =IF(A24<>"", AL24*(1+$X$6/CompoundingRate)^-(AH24/(365/CompoundingRate)), "") -> -7249 | AQ24: =IF(AQ23<$AP$3,AQ23+1,"") -> 44372 | AR24: =IF($AQ24<>"", INDEX($AC$3:$AC$1055, MATCH($AQ24,$A$3:$A$1055,1)), "") -> 172500 | AS24: =IF($AQ24<>"", INDEX(Inputs!$B$3:$B$101, MATCH($AQ24,Inputs!$A$3:$A$101,1)), "") -> 0.001 | AT24: =IF($AQ24<>"", AR24*AS24/365, "") -> 0.47260274 | AU24: =IF($AQ24<>"", SUMIFS($AL$3:$AL$1054, $A$3:$A$1054,$AQ24) + SUMIFS($M$3:$M$1054, $A$3:$A$1054,$AQ24)*IFERROR(AVERAGEIFS($L$3:$L$1054, $A$3:$A$1054,$AQ24, $M$3:$M$1054,">0"),0) - AT24, "") -> -0.47260274 | AV24: =IF(AQ24<>"", AU24*(1+$X$9/CompoundingRate)^-((AQ24-AQ$3)/(365/CompoundingRate)), "") -> -0.47260274
A25: 44393 | B25: Washer + Dryer | H25: 2669.95 | M25: =IF($A25<>"", IF(ISNUMBER(SEARCH("Debt Cost (est.)",B25)), SUMIFS(AT:AT, AQ:AQ, ">="&DATE("20"&RIGHT(LEFT(B25,4),2)-1,7,1), AQ:AQ, "<="&DATE("20"&RIGHT(LEFT(B25,4),2),6,30)), ""), "") | AA25: =IF($A25<>"", MIN(AB25,$P$3), "") -> 3450000 | AB25: =IF($A25<>"", AC25+AD25, "") -> 3450000 | AC25: =IF(A25<>"", AC24+D25+F25-G25, "") -> 517500 | AD25: =IF(A25<>"", AD24+C25-F25+G25, "") -> 2932500 | AE25: =IF(A26<>"", A26-A25, IF(A25<>"",IF(AC25<>0,TODAY()-A25,0), "")) -> 0 | AG25: =IF($A25<>"", I25+J25+E25-F25-H25, "") -> -2669.95 | AH25: =IF(A25<>"", A25-A$3, "") -> 42 | AI25: =IF(A25<>"", AG25*(1+$X$3)^-(AH25/365), "") -> -2669.95 | AL25: =IF($A25<>"", AG25-IF(ISNUMBER(K25),K25*L25,0), "") -> -2669.95 | AM25: =IF(A25<>"", AL25*(1+$X$6/CompoundingRate)^-(AH25/(365/CompoundingRate)), "") -> -2669.95 | AQ25: =IF(AQ24<$AP$3,AQ24+1,"") -> 44373 | AR25: =IF($AQ25<>"", INDEX($AC$3:$AC$1055, MATCH($AQ25,$A$3:$A$1055,1)), "") -> 172500 | AS25: =IF($AQ25<>"", INDEX(Inputs!$B$3:$B$101, MATCH($AQ25,Inputs!$A$3:$A$101,1)), "") -> 0.001 | AT25: =IF($AQ25<>"", AR25*AS25/365, "") -> 0.47260274 | AU25: =IF($AQ25<>"", SUMIFS($AL$3:$AL$1054, $A$3:$A$1054,$AQ25) + SUMIFS($M$3:$M$1054, $A$3:$A$1054,$AQ25)*IFERROR(AVERAGEIFS($L$3:$L$1054, $A$3:$A$1054,$AQ25, $M$3:$M$1054,">0"),0) - AT25, "") -> -0.47260274 | AV25: =IF(AQ25<>"", AU25*(1+$X$9/CompoundingRate)^-((AQ25-AQ$3)/(365/CompoundingRate)), "") -> -0.47260274
A26: 44393 | B26: Air Conditioning | H26: 198 | M26: =IF($A26<>"", IF(ISNUMBER(SEARCH("Debt Cost (est.)",B26)), SUMIFS(AT:AT, AQ:AQ, ">="&DATE("20"&RIGHT(LEFT(B26,4),2)-1,7,1), AQ:AQ, "<="&DATE("20"&RIGHT(LEFT(B26,4),2),6,30)), ""), "") | AA26: =IF($A26<>"", MIN(AB26,$P$3), "") -> 3450000 | AB26: =IF($A26<>"", AC26+AD26, "") -> 3450000 | AC26: =IF(A26<>"", AC25+D26+F26-G26, "") -> 517500 | AD26: =IF(A26<>"", AD25+C26-F26+G26, "") -> 2932500 | AE26: =IF(A27<>"", A27-A26, IF(A26<>"",IF(AC26<>0,TODAY()-A26,0), "")) -> 0 | AG26: =IF($A26<>"", I26+J26+E26-F26-H26, "") -> -198 | AH26: =IF(A26<>"", A26-A$3, "") -> 42 | AI26: =IF(A26<>"", AG26*(1+$X$3)^-(AH26/365), "") -> -198 | AL26: =IF($A26<>"", AG26-IF(ISNUMBER(K26),K26*L26,0), "") -> -198 | AM26: =IF(A26<>"", AL26*(1+$X$6/CompoundingRate)^-(AH26/(365/CompoundingRate)), "") -> -198 | AQ26: =IF(AQ25<$AP$3,AQ25+1,"") -> 44374 | AR26: =IF($AQ26<>"", INDEX($AC$3:$AC$1055, MATCH($AQ26,$A$3:$A$1055,1)), "") -> 172500 | AS26: =IF($AQ26<>"", INDEX(Inputs!$B$3:$B$101, MATCH($AQ26,Inputs!$A$3:$A$101,1)), "") -> 0.001 | AT26: =IF($AQ26<>"", AR26*AS26/365, "") -> 0.47260274 | AU26: =IF($AQ26<>"", SUMIFS($AL$3:$AL$1054, $A$3:$A$1054,$AQ26) + SUMIFS($M$3:$M$1054, $A$3:$A$1054,$AQ26)*IFERROR(AVERAGEIFS($L$3:$L$1054, $A$3:$A$1054,$AQ26, $M$3:$M$1054,">0"),0) - AT26, "") -> -0.47260274 | AV26: =IF(AQ26<>"", AU26*(1+$X$9/CompoundingRate)^-((AQ26-AQ$3)/(365/CompoundingRate)), "") -> -0.47260274
A27: 44393 | B27: General Repairs | H27: 720 | M27: =IF($A27<>"", IF(ISNUMBER(SEARCH("Debt Cost (est.)",B27)), SUMIFS(AT:AT, AQ:AQ, ">="&DATE("20"&RIGHT(LEFT(B27,4),2)-1,7,1), AQ:AQ, "<="&DATE("20"&RIGHT(LEFT(B27,4),2),6,30)), ""), "") | AA27: =IF($A27<>"", MIN(AB27,$P$3), "") -> 3450000 | AB27: =IF($A27<>"", AC27+AD27, "") -> 3450000 | AC27: =IF(A27<>"", AC26+D27+F27-G27, "") -> 517500 | AD27: =IF(A27<>"", AD26+C27-F27+G27, "") -> 2932500 | AE27: =IF(A28<>"", A28-A27, IF(A27<>"",IF(AC27<>0,TODAY()-A27,0), "")) -> 0 | AG27: =IF($A27<>"", I27+J27+E27-F27-H27, "") -> -720 | AH27: =IF(A27<>"", A27-A$3, "") -> 42 | AI27: =IF(A27<>"", AG27*(1+$X$3)^-(AH27/365), "") -> -720 | AL27: =IF($A27<>"", AG27-IF(ISNUMBER(K27),K27*L27,0), "") -> -720 | AM27: =IF(A27<>"", AL27*(1+$X$6/CompoundingRate)^-(AH27/(365/CompoundingRate)), "") -> -720 | AQ27: =IF(AQ26<$AP$3,AQ26+1,"") -> 44375 | AR27: =IF($AQ27<>"", INDEX($AC$3:$AC$1055, MATCH($AQ27,$A$3:$A$1055,1)), "") -> 172500 | AS27: =IF($AQ27<>"", INDEX(Inputs!$B$3:$B$101, MATCH($AQ27,Inputs!$A$3:$A$101,1)), "") -> 0.001 | AT27: =IF($AQ27<>"", AR27*AS27/365, "") -> 0.47260274 | AU27: =IF($AQ27<>"", SUMIFS($AL$3:$AL$1054, $A$3:$A$1054,$AQ27) + SUMIFS($M$3:$M$1054, $A$3:$A$1054,$AQ27)*IFERROR(AVERAGEIFS($L$3:$L$1054, $A$3:$A$1054,$AQ27, $M$3:$M$1054,">0"),0) - AT27, "") -> -0.47260274 | AV27: =IF(AQ27<>"", AU27*(1+$X$9/CompoundingRate)^-((AQ27-AQ$3)/(365/CompoundingRate)), "") -> -0.47260274
A28: 44393 | B28: Rent - Andre | I28: 1900 | M28: =IF($A28<>"", IF(ISNUMBER(SEARCH("Debt Cost (est.)",B28)), SUMIFS(AT:AT, AQ:AQ, ">="&DATE("20"&RIGHT(LEFT(B28,4),2)-1,7,1), AQ:AQ, "<="&DATE("20"&RIGHT(LEFT(B28,4),2),6,30)), ""), "") | AA28: =IF($A28<>"", MIN(AB28,$P$3), "") -> 3450000 | AB28: =IF($A28<>"", AC28+AD28, "") -> 3450000 | AC28: =IF(A28<>"", AC27+D28+F28-G28, "") -> 517500 | AD28: =IF(A28<>"", AD27+C28-F28+G28, "") -> 2932500 | AE28: =IF(A29<>"", A29-A28, IF(A28<>"",IF(AC28<>0,TODAY()-A28,0), "")) -> 3 | AG28: =IF($A28<>"", I28+J28+E28-F28-H28, "") -> 1900 | AH28: =IF(A28<>"", A28-A$3, "") -> 42 | AI28: =IF(A28<>"", AG28*(1+$X$3)^-(AH28/365), "") -> 1900 | AL28: =IF($A28<>"", AG28-IF(ISNUMBER(K28),K28*L28,0), "") -> 1900 | AM28: =IF(A28<>"", AL28*(1+$X$6/CompoundingRate)^-(AH28/(365/CompoundingRate)), "") -> 1900 | AQ28: =IF(AQ27<$AP$3,AQ27+1,"") -> 44376 | AR28: =IF($AQ28<>"", INDEX($AC$3:$AC$1055, MATCH($AQ28,$A$3:$A$1055,1)), "") -> 172500 | AS28: =IF($AQ28<>"", INDEX(Inputs!$B$3:$B$101, MATCH($AQ28,Inputs!$A$3:$A$101,1)), "") -> 0.001 | AT28: =IF($AQ28<>"", AR28*AS28/365, "") -> 0.47260274 | AU28: =IF($AQ28<>"", SUMIFS($AL$3:$AL$1054, $A$3:$A$1054,$AQ28) + SUMIFS($M$3:$M$1054, $A$3:$A$1054,$AQ28)*IFERROR(AVERAGEIFS($L$3:$L$1054, $A$3:$A$1054,$AQ28, $M$3:$M$1054,">0"),0) - AT28, "") -> -0.47260274 | AV28: =IF(AQ28<>"", AU28*(1+$X$9/CompoundingRate)^-((AQ28-AQ$3)/(365/CompoundingRate)), "") -> -0.47260274
A29: 44396 | B29: Landlords Insurance | H29: 587.76 | M29: =IF($A29<>"", IF(ISNUMBER(SEARCH("Debt Cost (est.)",B29)), SUMIFS(AT:AT, AQ:AQ, ">="&DATE("20"&RIGHT(LEFT(B29,4),2)-1,7,1), AQ:AQ, "<="&DATE("20"&RIGHT(LEFT(B29,4),2),6,30)), ""), "") | AA29: =IF($A29<>"", MIN(AB29,$P$3), "") -> 3450000 | AB29: =IF($A29<>"", AC29+AD29, "") -> 3450000 | AC29: =IF(A29<>"", AC28+D29+F29-G29, "") -> 517500 | AD29: =IF(A29<>"", AD28+C29-F29+G29, "") -> 2932500 | AE29: =IF(A30<>"", A30-A29, IF(A29<>"",IF(AC29<>0,TODAY()-A29,0), "")) -> 4 | AG29: =IF($A29<>"", I29+J29+E29-F29-H29, "") -> -587.76 | AH29: =IF(A29<>"", A29-A$3, "") -> 45 | AI29: =IF(A29<>"", AG29*(1+$X$3)^-(AH29/365), "") -> -587.76 | AL29: =IF($A29<>"", AG29-IF(ISNUMBER(K29),K29*L29,0), "") -> -587.76 | AM29: =IF(A29<>"", AL29*(1+$X$6/CompoundingRate)^-(AH29/(365/CompoundingRate)), "") -> -587.76 | AQ29: =IF(AQ28<$AP$3,AQ28+1,"") -> 44377 | AR29: =IF($AQ29<>"", INDEX($AC$3:$AC$1055, MATCH($AQ29,$A$3:$A$1055,1)), "") -> 172500 | AS29: =IF($AQ29<>"", INDEX(Inputs!$B$3:$B$101, MATCH($AQ29,Inputs!$A$3:$A$101,1)), "") -> 0.001 | AT29: =IF($AQ29<>"", AR29*AS29/365, "") -> 0.47260274 | AU29: =IF($AQ29<>"", SUMIFS($AL$3:$AL$1054, $A$3:$A$1054,$AQ29) + SUMIFS($M$3:$M$1054, $A$3:$A$1054,$AQ29)*IFERROR(AVERAGEIFS($L$3:$L$1054, $A$3:$A$1054,$AQ29, $M$3:$M$1054,">0"),0) - AT29, "") -> 3.6744863 | AV29: =IF(AQ29<>"", AU29*(1+$X$9/CompoundingRate)^-((AQ29-AQ$3)/(365/CompoundingRate)), "") -> 3.6744863
A30: 44400 | B30: Rent - Andre | I30: 1900 | M30: =IF($A30<>"", IF(ISNUMBER(SEARCH("Debt Cost (est.)",B30)), SUMIFS(AT:AT, AQ:AQ, ">="&DATE("20"&RIGHT(LEFT(B30,4),2)-1,7,1), AQ:AQ, "<="&DATE("20"&RIGHT(LEFT(B30,4),2),6,30)), ""), "") | AA30: =IF($A30<>"", MIN(AB30,$P$3), "") -> 3450000 | AB30: =IF($A30<>"", AC30+AD30, "") -> 3450000 | AC30: =IF(A30<>"", AC29+D30+F30-G30, "") -> 517500 | AD30: =IF(A30<>"", AD29+C30-F30+G30, "") -> 2932500 | AE30: =IF(A31<>"", A31-A30, IF(A30<>"",IF(AC30<>0,TODAY()-A30,0), "")) -> 7 | AG30: =IF($A30<>"", I30+J30+E30-F30-H30, "") -> 1900 | AH30: =IF(A30<>"", A30-A$3, "") -> 49 | AI30: =IF(A30<>"", AG30*(1+$X$3)^-(AH30/365), "") -> 1900 | AL30: =IF($A30<>"", AG30-IF(ISNUMBER(K30),K30*L30,0), "") -> 1900 | AM30: =IF(A30<>"", AL30*(1+$X$6/CompoundingRate)^-(AH30/(365/CompoundingRate)), "") -> 1900 | AQ30: =IF(AQ29<$AP$3,AQ29+1,"") -> 44378 | AR30: =IF($AQ30<>"", INDEX($AC$3:$AC$1055, MATCH($AQ30,$A$3:$A$1055,1)), "") -> 172500 | AS30: =IF($AQ30<>"", INDEX(Inputs!$B$3:$B$101, MATCH($AQ30,Inputs!$A$3:$A$101,1)), "") -> 0.001 | AT30: =IF($AQ30<>"", AR30*AS30/365, "") -> 0.47260274 | AU30: =IF($AQ30<>"", SUMIFS($AL$3:$AL$1054, $A$3:$A$1054,$AQ30) + SUMIFS($M$3:$M$1054, $A$3:$A$1054,$AQ30)*IFERROR(AVERAGEIFS($L$3:$L$1054, $A$3:$A$1054,$AQ30, $M$3:$M$1054,">0"),0) - AT30, "") -> -0.47260274 | AV30: =IF(AQ30<>"", AU30*(1+$X$9/CompoundingRate)^-((AQ30-AQ$3)/(365/CompoundingRate)), "") -> -0.47260274
A31: 44407 | B31: Rent - Andre | I31: 1900 | M31: =IF($A31<>"", IF(ISNUMBER(SEARCH("Debt Cost (est.)",B31)), SUMIFS(AT:AT, AQ:AQ, ">="&DATE("20"&RIGHT(LEFT(B31,4),2)-1,7,1), AQ:AQ, "<="&DATE("20"&RIGHT(LEFT(B31,4),2),6,30)), ""), "") | AA31: =IF($A31<>"", MIN(AB31,$P$3), "") -> 3450000 | AB31: =IF($A31<>"", AC31+AD31, "") -> 3450000 | AC31: =IF(A31<>"", AC30+D31+F31-G31, "") -> 517500 | AD31: =IF(A31<>"", AD30+C31-F31+G31, "") -> 2932500 | AE31: =IF(A32<>"", A32-A31, IF(A31<>"",IF(AC31<>0,TODAY()-A31,0), "")) -> 0 | AG31: =IF($A31<>"", I31+J31+E31-F31-H31, "") -> 1900 | AH31: =IF(A31<>"", A31-A$3, "") -> 56 | AI31: =IF(A31<>"", AG31*(1+$X$3)^-(AH31/365), "") -> 1900 | AL31: =IF($A31<>"", AG31-IF(ISNUMBER(K31),K31*L31,0), "") -> 1900 | AM31: =IF(A31<>"", AL31*(1+$X$6/CompoundingRate)^-(AH31/(365/CompoundingRate)), "") -> 1900 | AQ31: =IF(AQ30<$AP$3,AQ30+1,"") -> 44379 | AR31: =IF($AQ31<>"", INDEX($AC$3:$AC$1055, MATCH($AQ31,$A$3:$A$1055,1)), "") -> 172500 | AS31: =IF($AQ31<>"", INDEX(Inputs!$B$3:$B$101, MATCH($AQ31,Inputs!$A$3:$A$101,1)), "") -> 0.001 | AT31: =IF($AQ31<>"", AR31*AS31/365, "") -> 0.47260274 | AU31: =IF($AQ31<>"", SUMIFS($AL$3:$AL$1054, $A$3:$A$1054,$AQ31) + SUMIFS($M$3:$M$1054, $A$3:$A$1054,$AQ31)*IFERROR(AVERAGEIFS($L$3:$L$1054, $A$3:$A$1054,$AQ31, $M$3:$M$1054,">0"),0) - AT31, "") -> -0.47260274 | AV31: =IF(AQ31<>"", AU31*(1+$X$9/CompoundingRate)^-((AQ31-AQ$3)/(365/CompoundingRate)), "") -> -0.47260274
A32: 44407 | B32: NAB #3063 - Interest | G32: 1940.67 | M32: =IF($A32<>"", IF(ISNUMBER(SEARCH("Debt Cost (est.)",B32)), SUMIFS(AT:AT, AQ:AQ, ">="&DATE("20"&RIGHT(LEFT(B32,4),2)-1,7,1), AQ:AQ, "<="&DATE("20"&RIGHT(LEFT(B32,4),2),6,30)), ""), "") | AA32: =IF($A32<>"", MIN(AB32,$P$3), "") -> 3450000 | AB32: =IF($A32<>"", AC32+AD32, "") -> 3450000 | AC32: =IF(A32<>"", AC31+D32+F32-G32, "") -> 515559.33 | AD32: =IF(A32<>"", AD31+C32-F32+G32, "") -> 2934440.7 | AE32: =IF(A33<>"", A33-A32, IF(A32<>"",IF(AC32<>0,TODAY()-A32,0), "")) -> 0 | AG32: =IF($A32<>"", I32+J32+E32-F32-H32, "") -> 0 | AH32: =IF(A32<>"", A32-A$3, "") -> 56 | AI32: =IF(A32<>"", AG32*(1+$X$3)^-(AH32/365), "") -> 0 | AL32: =IF($A32<>"", AG32-IF(ISNUMBER(K32),K32*L32,0), "") -> 0 | AM32: =IF(A32<>"", AL32*(1+$X$6/CompoundingRate)^-(AH32/(365/CompoundingRate)), "") -> 0 | AQ32: =IF(AQ31<$AP$3,AQ31+1,"") -> 44380 | AR32: =IF($AQ32<>"", INDEX($AC$3:$AC$1055, MATCH($AQ32,$A$3:$A$1055,1)), "") -> 172500 | AS32: =IF($AQ32<>"", INDEX(Inputs!$B$3:$B$101, MATCH($AQ32,Inputs!$A$3:$A$101,1)), "") -> 0.001 | AT32: =IF($AQ32<>"", AR32*AS32/365, "") -> 0.47260274 | AU32: =IF($AQ32<>"", SUMIFS($AL$3:$AL$1054, $A$3:$A$1054,$AQ32) + SUMIFS($M$3:$M$1054, $A$3:$A$1054,$AQ32)*IFERROR(AVERAGEIFS($L$3:$L$1054, $A$3:$A$1054,$AQ32, $M$3:$M$1054,">0"),0) - AT32, "") -> -0.47260274 | AV32: =IF(AQ32<>"", AU32*(1+$X$9/CompoundingRate)^-((AQ32-AQ$3)/(365/CompoundingRate)), "") -> -0.47260274
A33: 44407 | B33: NAB #2157 - Interest | G33: =171.71-2.44 -> 169.27 | M33: =IF($A33<>"", IF(ISNUMBER(SEARCH("Debt Cost (est.)",B33)), SUMIFS(AT:AT, AQ:AQ, ">="&DATE("20"&RIGHT(LEFT(B33,4),2)-1,7,1), AQ:AQ, "<="&DATE("20"&RIGHT(LEFT(B33,4),2),6,30)), ""), "") | AA33: =IF($A33<>"", MIN(AB33,$P$3), "") -> 3450000 | AB33: =IF($A33<>"", AC33+AD33, "") -> 3450000 | AC33: =IF(A33<>"", AC32+D33+F33-G33, "") -> 515390.06 | AD33: =IF(A33<>"", AD32+C33-F33+G33, "") -> 2934609.9 | AE33: =IF(A34<>"", A34-A33, IF(A33<>"",IF(AC33<>0,TODAY()-A33,0), "")) -> 7 | AG33: =IF($A33<>"", I33+J33+E33-F33-H33, "") -> 0 | AH33: =IF(A33<>"", A33-A$3, "") -> 56 | AI33: =IF(A33<>"", AG33*(1+$X$3)^-(AH33/365), "") -> 0 | AL33: =IF($A33<>"", AG33-IF(ISNUMBER(K33),K33*L33,0), "") -> 0 | AM33: =IF(A33<>"", AL33*(1+$X$6/CompoundingRate)^-(AH33/(365/CompoundingRate)), "") -> 0 | AQ33: =IF(AQ32<$AP$3,AQ32+1,"") -> 44381 | AR33: =IF($AQ33<>"", INDEX($AC$3:$AC$1055, MATCH($AQ33,$A$3:$A$1055,1)), "") -> 172500 | AS33: =IF($AQ33<>"", INDEX(Inputs!$B$3:$B$101, MATCH($AQ33,Inputs!$A$3:$A$101,1)), "") -> 0.001 | AT33: =IF($AQ33<>"", AR33*AS33/365, "") -> 0.47260274 | AU33: =IF($AQ33<>"", SUMIFS($AL$3:$AL$1054, $A$3:$A$1054,$AQ33) + SUMIFS($M$3:$M$1054, $A$3:$A$1054,$AQ33)*IFERROR(AVERAGEIFS($L$3:$L$1054, $A$3:$A$1054,$AQ33, $M$3:$M$1054,">0"),0) - AT33, "") -> -0.47260274 | AV33: =IF(AQ33<>"", AU33*(1+$X$9/CompoundingRate)^-((AQ33-AQ$3)/(365/CompoundingRate)), "") -> -0.47260274
A34: 44414 | B34: Rent - Andre | I34: 1900 | M34: =IF($A34<>"", IF(ISNUMBER(SEARCH("Debt Cost (est.)",B34)), SUMIFS(AT:AT, AQ:AQ, ">="&DATE("20"&RIGHT(LEFT(B34,4),2)-1,7,1), AQ:AQ, "<="&DATE("20"&RIGHT(LEFT(B34,4),2),6,30)), ""), "") | AA34: =IF($A34<>"", MIN(AB34,$P$3), "") -> 3450000 | AB34: =IF($A34<>"", AC34+AD34, "") -> 3450000 | AC34: =IF(A34<>"", AC33+D34+F34-G34, "") -> 515390.06 | AD34: =IF(A34<>"", AD33+C34-F34+G34, "") -> 2934609.9 | AE34: =IF(A35<>"", A35-A34, IF(A34<>"",IF(AC34<>0,TODAY()-A34,0), "")) -> 7 | AG34: =IF($A34<>"", I34+J34+E34-F34-H34, "") -> 1900 | AH34: =IF(A34<>"", A34-A$3, "") -> 63 | AI34: =IF(A34<>"", AG34*(1+$X$3)^-(AH34/365), "") -> 1900 | AL34: =IF($A34<>"", AG34-IF(ISNUMBER(K34),K34*L34,0), "") -> 1900 | AM34: =IF(A34<>"", AL34*(1+$X$6/CompoundingRate)^-(AH34/(365/CompoundingRate)), "") -> 1900 | AQ34: =IF(AQ33<$AP$3,AQ33+1,"") -> 44382 | AR34: =IF($AQ34<>"", INDEX($AC$3:$AC$1055, MATCH($AQ34,$A$3:$A$1055,1)), "") -> 172500 | AS34: =IF($AQ34<>"", INDEX(Inputs!$B$3:$B$101, MATCH($AQ34,Inputs!$A$3:$A$101,1)), "") -> 0.001 | AT34: =IF($AQ34<>"", AR34*AS34/365, "") -> 0.47260274 | AU34: =IF($AQ34<>"", SUMIFS($AL$3:$AL$1054, $A$3:$A$1054,$AQ34) + SUMIFS($M$3:$M$1054, $A$3:$A$1054,$AQ34)*IFERROR(AVERAGEIFS($L$3:$L$1054, $A$3:$A$1054,$AQ34, $M$3:$M$1054,">0"),0) - AT34, "") -> -0.47260274 | AV34: =IF(AQ34<>"", AU34*(1+$X$9/CompoundingRate)^-((AQ34-AQ$3)/(365/CompoundingRate)), "") -> -0.47260274
A35: 44421 | B35: Rent - Andre | I35: 1900 | M35: =IF($A35<>"", IF(ISNUMBER(SEARCH("Debt Cost (est.)",B35)), SUMIFS(AT:AT, AQ:AQ, ">="&DATE("20"&RIGHT(LEFT(B35,4),2)-1,7,1), AQ:AQ, "<="&DATE("20"&RIGHT(LEFT(B35,4),2),6,30)), ""), "") | AA35: =IF($A35<>"", MIN(AB35,$P$3), "") -> 3450000 | AB35: =IF($A35<>"", AC35+AD35, "") -> 3450000 | AC35: =IF(A35<>"", AC34+D35+F35-G35, "") -> 515390.06 | AD35: =IF(A35<>"", AD34+C35-F35+G35, "") -> 2934609.9 | AE35: =IF(A36<>"", A36-A35, IF(A35<>"",IF(AC35<>0,TODAY()-A35,0), "")) -> 3 | AG35: =IF($A35<>"", I35+J35+E35-F35-H35, "") -> 1900 | AH35: =IF(A35<>"", A35-A$3, "") -> 70 | AI35: =IF(A35<>"", AG35*(1+$X$3)^-(AH35/365), "") -> 1900 | AL35: =IF($A35<>"", AG35-IF(ISNUMBER(K35),K35*L35,0), "") -> 1900 | AM35: =IF(A35<>"", AL35*(1+$X$6/CompoundingRate)^-(AH35/(365/CompoundingRate)), "") -> 1900 | AQ35: =IF(AQ34<$AP$3,AQ34+1,"") -> 44383 | AR35: =IF($AQ35<>"", INDEX($AC$3:$AC$1055, MATCH($AQ35,$A$3:$A$1055,1)), "") -> 172500 | AS35: =IF($AQ35<>"", INDEX(Inputs!$B$3:$B$101, MATCH($AQ35,Inputs!$A$3:$A$101,1)), "") -> 0.001 | AT35: =IF($AQ35<>"", AR35*AS35/365, "") -> 0.47260274 | AU35: =IF($AQ35<>"", SUMIFS($AL$3:$AL$1054, $A$3:$A$1054,$AQ35) + SUMIFS($M$3:$M$1054, $A$3:$A$1054,$AQ35)*IFERROR(AVERAGEIFS($L$3:$L$1054, $A$3:$A$1054,$AQ35, $M$3:$M$1054,">0"),0) - AT35, "") -> -0.47260274 | AV35: =IF(AQ35<>"", AU35*(1+$X$9/CompoundingRate)^-((AQ35-AQ$3)/(365/CompoundingRate)), "") -> -0.47260274
A36: 44424 | B36: NAB #3063 - Repayment | F36: 9818.51 | M36: =IF($A36<>"", IF(ISNUMBER(SEARCH("Debt Cost (est.)",B36)), SUMIFS(AT:AT, AQ:AQ, ">="&DATE("20"&RIGHT(LEFT(B36,4),2)-1,7,1), AQ:AQ, "<="&DATE("20"&RIGHT(LEFT(B36,4),2),6,30)), ""), "") | AA36: =IF($A36<>"", MIN(AB36,$P$3), "") -> 3450000 | AB36: =IF($A36<>"", AC36+AD36, "") -> 3450000 | AC36: =IF(A36<>"", AC35+D36+F36-G36, "") -> 525208.57 | AD36: =IF(A36<>"", AD35+C36-F36+G36, "") -> 2924791.4 | AE36: =IF(A37<>"", A37-A36, IF(A36<>"",IF(AC36<>0,TODAY()-A36,0), "")) -> 0 | AG36: =IF($A36<>"", I36+J36+E36-F36-H36, "") -> -9818.51 | AH36: =IF(A36<>"", A36-A$3, "") -> 73 | AI36: =IF(A36<>"", AG36*(1+$X$3)^-(AH36/365), "") -> -9818.51 | AL36: =IF($A36<>"", AG36-IF(ISNUMBER(K36),K36*L36,0), "") -> -9818.51 | AM36: =IF(A36<>"", AL36*(1+$X$6/CompoundingRate)^-(AH36/(365/CompoundingRate)), "") -> -9818.51 | AQ36: =IF(AQ35<$AP$3,AQ35+1,"") -> 44384 | AR36: =IF($AQ36<>"", INDEX($AC$3:$AC$1055, MATCH($AQ36,$A$3:$A$1055,1)), "") -> 172500 | AS36: =IF($AQ36<>"", INDEX(Inputs!$B$3:$B$101, MATCH($AQ36,Inputs!$A$3:$A$101,1)), "") -> 0.001 | AT36: =IF($AQ36<>"", AR36*AS36/365, "") -> 0.47260274 | AU36: =IF($AQ36<>"", SUMIFS($AL$3:$AL$1054, $A$3:$A$1054,$AQ36) + SUMIFS($M$3:$M$1054, $A$3:$A$1054,$AQ36)*IFERROR(AVERAGEIFS($L$3:$L$1054, $A$3:$A$1054,$AQ36, $M$3:$M$1054,">0"),0) - AT36, "") -> -0.47260274 | AV36: =IF(AQ36<>"", AU36*(1+$X$9/CompoundingRate)^-((AQ36-AQ$3)/(365/CompoundingRate)), "") -> -0.47260274
A37: 44424 | B37: NAB #2157 - Repayment | F37: 2232.44 | M37: =IF($A37<>"", IF(ISNUMBER(SEARCH("Debt Cost (est.)",B37)), SUMIFS(AT:AT, AQ:AQ, ">="&DATE("20"&RIGHT(LEFT(B37,4),2)-1,7,1), AQ:AQ, "<="&DATE("20"&RIGHT(LEFT(B37,4),2),6,30)), ""), "") | AA37: =IF($A37<>"", MIN(AB37,$P$3), "") -> 3450000 | AB37: =IF($A37<>"", AC37+AD37, "") -> 3450000 | AC37: =IF(A37<>"", AC36+D37+F37-G37, "") -> 527441.01 | AD37: =IF(A37<>"", AD36+C37-F37+G37, "") -> 2922559 | AE37: =IF(A38<>"", A38-A37, IF(A37<>"",IF(AC37<>0,TODAY()-A37,0), "")) -> 3 | AG37: =IF($A37<>"", I37+J37+E37-F37-H37, "") -> -2232.44 | AH37: =IF(A37<>"", A37-A$3, "") -> 73 | AI37: =IF(A37<>"", AG37*(1+$X$3)^-(AH37/365), "") -> -2232.44 | AL37: =IF($A37<>"", AG37-IF(ISNUMBER(K37),K37*L37,0), "") -> -2232.44 | AM37: =IF(A37<>"", AL37*(1+$X$6/CompoundingRate)^-(AH37/(365/CompoundingRate)), "") -> -2232.44 | AQ37: =IF(AQ36<$AP$3,AQ36+1,"") -> 44385 | AR37: =IF($AQ37<>"", INDEX($AC$3:$AC$1055, MATCH($AQ37,$A$3:$A$1055,1)), "") -> 172500 | AS37: =IF($AQ37<>"", INDEX(Inputs!$B$3:$B$101, MATCH($AQ37,Inputs!$A$3:$A$101,1)), "") -> 0.001 | AT37: =IF($AQ37<>"", AR37*AS37/365, "") -> 0.47260274 | AU37: =IF($AQ37<>"", SUMIFS($AL$3:$AL$1054, $A$3:$A$1054,$AQ37) + SUMIFS($M$3:$M$1054, $A$3:$A$1054,$AQ37)*IFERROR(AVERAGEIFS($L$3:$L$1054, $A$3:$A$1054,$AQ37, $M$3:$M$1054,">0"),0) - AT37, "") -> -0.47260274 | AV37: =IF(AQ37<>"", AU37*(1+$X$9/CompoundingRate)^-((AQ37-AQ$3)/(365/CompoundingRate)), "") -> -0.47260274
A38: 44427 | B38: Lawyer Fees Return | H38: -335.05 | M38: =IF($A38<>"", IF(ISNUMBER(SEARCH("Debt Cost (est.)",B38)), SUMIFS(AT:AT, AQ:AQ, ">="&DATE("20"&RIGHT(LEFT(B38,4),2)-1,7,1), AQ:AQ, "<="&DATE("20"&RIGHT(LEFT(B38,4),2),6,30)), ""), "") | AA38: =IF($A38<>"", MIN(AB38,$P$3), "") -> 3450000 | AB38: =IF($A38<>"", AC38+AD38, "") -> 3450000 | AC38: =IF(A38<>"", AC37+D38+F38-G38, "") -> 527441.01 | AD38: =IF(A38<>"", AD37+C38-F38+G38, "") -> 2922559 | AE38: =IF(A39<>"", A39-A38, IF(A38<>"",IF(AC38<>0,TODAY()-A38,0), "")) -> 1 | AG38: =IF($A38<>"", I38+J38+E38-F38-H38, "") -> 335.05 | AH38: =IF(A38<>"", A38-A$3, "") -> 76 | AI38: =IF(A38<>"", AG38*(1+$X$3)^-(AH38/365), "") -> 335.05 | AL38: =IF($A38<>"", AG38-IF(ISNUMBER(K38),K38*L38,0), "") -> 335.05 | AM38: =IF(A38<>"", AL38*(1+$X$6/CompoundingRate)^-(AH38/(365/CompoundingRate)), "") -> 335.05 | AQ38: =IF(AQ37<$AP$3,AQ37+1,"") -> 44386 | AR38: =IF($AQ38<>"", INDEX($AC$3:$AC$1055, MATCH($AQ38,$A$3:$A$1055,1)), "") -> 172500 | AS38: =IF($AQ38<>"", INDEX(Inputs!$B$3:$B$101, MATCH($AQ38,Inputs!$A$3:$A$101,1)), "") -> 0.001 | AT38: =IF($AQ38<>"", AR38*AS38/365, "") -> 0.47260274 | AU38: =IF($AQ38<>"", SUMIFS($AL$3:$AL$1054, $A$3:$A$1054,$AQ38) + SUMIFS($M$3:$M$1054, $A$3:$A$1054,$AQ38)*IFERROR(AVERAGEIFS($L$3:$L$1054, $A$3:$A$1054,$AQ38, $M$3:$M$1054,">0"),0) - AT38, "") -> -0.47260274 | AV38: =IF(AQ38<>"", AU38*(1+$X$9/CompoundingRate)^-((AQ38-AQ$3)/(365/CompoundingRate)), "") -> -0.47260274
A39: 44428 | B39: Rent - Andre | I39: 1900 | M39: =IF($A39<>"", IF(ISNUMBER(SEARCH("Debt Cost (est.)",B39)), SUMIFS(AT:AT, AQ:AQ, ">="&DATE("20"&RIGHT(LEFT(B39,4),2)-1,7,1), AQ:AQ, "<="&DATE("20"&RIGHT(LEFT(B39,4),2),6,30)), ""), "") | AA39: =IF($A39<>"", MIN(AB39,$P$3), "") -> 3450000 | AB39: =IF($A39<>"", AC39+AD39, "") -> 3450000 | AC39: =IF(A39<>"", AC38+D39+F39-G39, "") -> 527441.01 | AD39: =IF(A39<>"", AD38+C39-F39+G39, "") -> 2922559 | AE39: =IF(A40<>"", A40-A39, IF(A39<>"",IF(AC39<>0,TODAY()-A39,0), "")) -> 7 | AG39: =IF($A39<>"", I39+J39+E39-F39-H39, "") -> 1900 | AH39: =IF(A39<>"", A39-A$3, "") -> 77 | AI39: =IF(A39<>"", AG39*(1+$X$3)^-(AH39/365), "") -> 1900 | AL39: =IF($A39<>"", AG39-IF(ISNUMBER(K39),K39*L39,0), "") -> 1900 | AM39: =IF(A39<>"", AL39*(1+$X$6/CompoundingRate)^-(AH39/(365/CompoundingRate)), "") -> 1900 | AQ39: =IF(AQ38<$AP$3,AQ38+1,"") -> 44387 | AR39: =IF($AQ39<>"", INDEX($AC$3:$AC$1055, MATCH($AQ39,$A$3:$A$1055,1)), "") -> 172500 | AS39: =IF($AQ39<>"", INDEX(Inputs!$B$3:$B$101, MATCH($AQ39,Inputs!$A$3:$A$101,1)), "") -> 0.001 | AT39: =IF($AQ39<>"", AR39*AS39/365, "") -> 0.47260274 | AU39: =IF($AQ39<>"", SUMIFS($AL$3:$AL$1054, $A$3:$A$1054,$AQ39) + SUMIFS($M$3:$M$1054, $A$3:$A$1054,$AQ39)*IFERROR(AVERAGEIFS($L$3:$L$1054, $A$3:$A$1054,$AQ39, $M$3:$M$1054,">0"),0) - AT39, "") -> -0.47260274 | AV39: =IF(AQ39<>"", AU39*(1+$X$9/CompoundingRate)^-((AQ39-AQ$3)/(365/CompoundingRate)), "") -> -0.47260274
A40: 44435 | B40: Rent - Andre | I40: 1900 | M40: =IF($A40<>"", IF(ISNUMBER(SEARCH("Debt Cost (est.)",B40)), SUMIFS(AT:AT, AQ:AQ, ">="&DATE("20"&RIGHT(LEFT(B40,4),2)-1,7,1), AQ:AQ, "<="&DATE("20"&RIGHT(LEFT(B40,4),2),6,30)), ""), "") | AA40: =IF($A40<>"", MIN(AB40,$P$3), "") -> 3450000 | AB40: =IF($A40<>"", AC40+AD40, "") -> 3450000 | AC40: =IF(A40<>"", AC39+D40+F40-G40, "") -> 527441.01 | AD40: =IF(A40<>"", AD39+C40-F40+G40, "") -> 2922559 | AE40: =IF(A41<>"", A41-A40, IF(A40<>"",IF(AC40<>0,TODAY()-A40,0), "")) -> 4 | AG40: =IF($A40<>"", I40+J40+E40-F40-H40, "") -> 1900 | AH40: =IF(A40<>"", A40-A$3, "") -> 84 | AI40: =IF(A40<>"", AG40*(1+$X$3)^-(AH40/365), "") -> 1900 | AL40: =IF($A40<>"", AG40-IF(ISNUMBER(K40),K40*L40,0), "") -> 1900 | AM40: =IF(A40<>"", AL40*(1+$X$6/CompoundingRate)^-(AH40/(365/CompoundingRate)), "") -> 1900 | AQ40: =IF(AQ39<$AP$3,AQ39+1,"") -> 44388 | AR40: =IF($AQ40<>"", INDEX($AC$3:$AC$1055, MATCH($AQ40,$A$3:$A$1055,1)), "") -> 172500 | AS40: =IF($AQ40<>"", INDEX(Inputs!$B$3:$B$101, MATCH($AQ40,Inputs!$A$3:$A$101,1)), "") -> 0.001 | AT40: =IF($AQ40<>"", AR40*AS40/365, "") -> 0.47260274 | AU40: =IF($AQ40<>"", SUMIFS($AL$3:$AL$1054, $A$3:$A$1054,$AQ40) + SUMIFS($M$3:$M$1054, $A$3:$A$1054,$AQ40)*IFERROR(AVERAGEIFS($L$3:$L$1054, $A$3:$A$1054,$AQ40, $M$3:$M$1054,">0"),0) - AT40, "") -> -0.47260274 | AV40: =IF(AQ40<>"", AU40*(1+$X$9/CompoundingRate)^-((AQ40-AQ$3)/(365/CompoundingRate)), "") -> -0.47260274
...

Sheet Inputs
A1: RBA Cash Rate | D1: Compounding Rate | F1: FX
A2: =[1]RBA!A1 -> AUD Date | B2: =[1]RBA!B1 -> AUD Rate | D2: =[1]CompoundingRate!$A$2 -> 12 | F2: =[1]FX!A1 -> Date | G2: =[1]FX!B1 -> AUD | H2: =[1]FX!C1 -> USD | I2: =[1]FX!D1 -> EUR | J2: =[1]FX!E1 -> CNY | K2: =[1]FX!F1 -> SGD | L2: =[1]FX!G1 -> GBP
